Workbook

Sheet clima
A1: omm_id | B1: fecha | C1: dia_año | D1: Tx | E1: Tn | F1: Tm | G1: Pp | H1: latitud | I1: declinación solar | J1: Fp | K1: ETO(H-S)
A2: 87480 | B2: 30317 | C2: =B2-DATE(YEAR(B2),1,1)+1 -> 1 | D2: 35.2 | E2: 21.1 | F2: 27.8 | G2: 1.4 | H2: -32.9036 | I2: =23.45*SIN(RADIANS(360/365*(C2-81))) -> -23.011637 | J2: =IFERROR(24 / PI() * ACOS(-TAN(RADIANS(H2)) * TAN(RADIANS(I2))), IF(-TAN(RADIANS(H2)) * TAN(RADIANS(I2)) >= 1, 0,24)) -> 14.126664 | K2: 6.5
A3: 87480 | B3: 30318 | C3: =B3-DATE(YEAR(B3),1,1)+1 -> 2 | D3: 28.4 | E3: 24.2 | F3: 27 | G3: 0 | H3: -32.9036 | I3: =23.45*SIN(RADIANS(360/365*(C3-81))) -> -22.930544 | J3: =IFERROR(24 / PI() * ACOS(-TAN(RADIANS(H3)) * TAN(RADIANS(I3))), IF(-TAN(RADIANS(H3)) * TAN(RADIANS(I3)) >= 1, 0,24)) -> 14.118082 | K3: 2.2
A4: 87480 | B4: 30319 | C4: =B4-DATE(YEAR(B4),1,1)+1 -> 3 | D4: 29.8 | E4: 22.5 | F4: 25.8 | G4: 0 | H4: -32.9036 | I4: =23.45*SIN(RADIANS(360/365*(C4-81))) -> -22.842656 | J4: =IFERROR(24 / PI() * ACOS(-TAN(RADIANS(H4)) * TAN(RADIANS(I4))), IF(-TAN(RADIANS(H4)) * TAN(RADIANS(I4)) >= 1, 0,24)) -> 14.108796 | K4: 6.9
A5: 87480 | B5: 30320 | C5: =B5-DATE(YEAR(B5),1,1)+1 -> 4 | D5: 31.3 | E5: 18.8 | F5: 25.2 | G5: 0.8 | H5: -32.9036 | I5: =23.45*SIN(RADIANS(360/365*(C5-81))) -> -22.747999 | J5: =IFERROR(24 / PI() * ACOS(-TAN(RADIANS(H5)) * TAN(RADIANS(I5))), IF(-TAN(RADIANS(H5)) * TAN(RADIANS(I5)) >= 1, 0,24)) -> 14.098811 | K5: 5.8
A6: 87480 | B6: 30321 | C6: =B6-DATE(YEAR(B6),1,1)+1 -> 5 | D6: 30.4 | E6: 18.3 | F6: 25.2 | G6: 0 | H6: -32.9036 | I6: =23.45*SIN(RADIANS(360/365*(C6-81))) -> -22.646602 | J6: =IFERROR(24 / PI() * ACOS(-TAN(RADIANS(H6)) * TAN(RADIANS(I6))), IF(-TAN(RADIANS(H6)) * TAN(RADIANS(I6)) >= 1, 0,24)) -> 14.088135 | K6: 6.9
A7: 87480 | B7: 30322 | C7: =B7-DATE(YEAR(B7),1,1)+1 -> 6 | D7: 29.5 | E7: 21.5 | F7: 26.1 | G7: 0 | H7: -32.9036 | I7: =23.45*SIN(RADIANS(360/365*(C7-81))) -> -22.538493 | J7: =IFERROR(24 / PI() * ACOS(-TAN(RADIANS(H7)) * TAN(RADIANS(I7))), IF(-TAN(RADIANS(H7)) * TAN(RADIANS(I7)) >= 1, 0,24)) -> 14.076774 | K7: 7.7
A8: 87480 | B8: 30323 | C8: =B8-DATE(YEAR(B8),1,1)+1 -> 7 | D8: 31.8 | E8: 20 | F8: 26.8 | G8: 0 | H8: -32.9036 | I8: =23.45*SIN(RADIANS(360/365*(C8-81))) -> -22.423707 | J8: =IFERROR(24 / PI() * ACOS(-TAN(RADIANS(H8)) * TAN(RADIANS(I8))), IF(-TAN(RADIANS(H8)) * TAN(RADIANS(I8)) >= 1, 0,24)) -> 14.064736 | K8: 6.2
A9: 87480 | B9: 30324 | C9: =B9-DATE(YEAR(B9),1,1)+1 -> 8 | D9: 32.8 | E9: 20.9 | F9: 27.2 | G9: 0 | H9: -32.9036 | I9: =23.45*SIN(RADIANS(360/365*(C9-81))) -> -22.302275 | J9: =IFERROR(24 / PI() * ACOS(-TAN(RADIANS(H9)) * TAN(RADIANS(I9))), IF(-TAN(RADIANS(H9)) * TAN(RADIANS(I9)) >= 1, 0,24)) -> 14.052029 | K9: 6
A10: 87480 | B10: 30325 | C10: =B10-DATE(YEAR(B10),1,1)+1 -> 9 | D10: 33 | E10: 23.5 | F10: 27.8 | G10: 0 | H10: -32.9036 | I10: =23.45*SIN(RADIANS(360/365*(C10-81))) -> -22.174235 | J10: =IFERROR(24 / PI() * ACOS(-TAN(RADIANS(H10)) * TAN(RADIANS(I10))), IF(-TAN(RADIANS(H10)) * TAN(RADIANS(I10)) >= 1, 0,24)) -> 14.03866 | K10: 7.4
A11: 87480 | B11: 30326 | C11: =B11-DATE(YEAR(B11),1,1)+1 -> 10 | D11: 32 | E11: 22.8 | F11: 27.4 | G11: 0 | H11: -32.9036 | I11: =23.45*SIN(RADIANS(360/365*(C11-81))) -> -22.039625 | J11: =IFERROR(24 / PI() * ACOS(-TAN(RADIANS(H11)) * TAN(RADIANS(I11))), IF(-TAN(RADIANS(H11)) * TAN(RADIANS(I11)) >= 1, 0,24)) -> 14.024638 | K11: 3.7
A12: 87480 | B12: 30327 | C12: =B12-DATE(YEAR(B12),1,1)+1 -> 11 | D12: 33.3 | E12: 22 | F12: 27.9 | G12: 0 | H12: -32.9036 | I12: =23.45*SIN(RADIANS(360/365*(C12-81))) -> -21.898483 | J12: =IFERROR(24 / PI() * ACOS(-TAN(RADIANS(H12)) * TAN(RADIANS(I12))), IF(-TAN(RADIANS(H12)) * TAN(RADIANS(I12)) >= 1, 0,24)) -> 14.009972 | K12: 4.3
A13: 87480 | B13: 30328 | C13: =B13-DATE(YEAR(B13),1,1)+1 -> 12 | D13: 32.8 | E13: 24 | F13: 28 | G13: 3.8 | H13: -32.9036 | I13: =23.45*SIN(RADIANS(360/365*(C13-81))) -> -21.750852 | J13: =IFERROR(24 / PI() * ACOS(-TAN(RADIANS(H13)) * TAN(RADIANS(I13))), IF(-TAN(RADIANS(H13)) * TAN(RADIANS(I13)) >= 1, 0,24)) -> 13.994671 | K13: 5.7
... A548: 87480 | B548: 30863 | C548: =B548-DATE(YEAR(B548),1,1)+1 -> 182 | D548: 18.5 | E548: 1.8 | F548: 12.8 | G548: 0 | H548: -32.9036 | I548: =23.45*SIN(RADIANS(360/365*(C548-81))) -> 23.120484 | J548: =IFERROR(24 / PI() * ACOS(-TAN(RADIANS(H548)) * TAN(RADIANS(I548))), IF(-TAN(RADIANS(H548)) * TAN(RADIANS(I548)) >= 1, 0,24)) -> 9.8617968 | K548: 6.5

Sheet suelos
A1: Localidad | B1: Codigo | C1: Serie Suelo | D1: Tipo Suelo | E1: U | F1: DR | G1: CN | H1: kl | I1: Um | J1: Horiz | K1: PFH | L1: PMP | M1: CC | N1: Sat
A2: Benito Juarez | B2: IN54BJUA01 | C2: Azul 80 | D2: PALEUDOL PETROCÁLCICO | E2: 10 | F2: 0.6 | G2: 81 | H2: 0.1 | I2: 0.5 | J2: Ap | K2: 20 | L2: 0.17 | M2: 0.31 | N2: 0.56
A3: Benito Juarez | J3: BAt | K3: 40 | L3: 0.22 | M3: 0.35 | N3: 0.5
A4: Benito Juarez | J4: Bt | K4: 60 | L4: 0.25 | M4: 0.37 | N4: 0.45
A5: Benito Juarez | J5: BC | K5: 80 | L5: 0.15 | M5: 0.27 | N5: 0.41
A6: Benito Juarez | B6: IN54BJUA03 | C6: Laprida 140 | D6: Argiudol tipico | E6: 10 | F6: 0.4 | G6: 79 | H6: 0.1 | I6: 0.5 | J6: AP | K6: 20 | L6: 0.15 | M6: 0.29 | N6: 0.54
A7: Benito Juarez | J7: B1 | K7: 40 | L7: 0.17 | M7: 0.3 | N7: 0.47
A8: Benito Juarez | J8: B2T | K8: 60 | L8: 0.19 | M8: 0.31 | N8: 0.41
A9: Benito Juarez | J9: B3 | K9: 90 | L9: 0.13 | M9: 0.26 | N9: 0.43
A10: Benito Juarez | J10: C | K10: 120 | L10: 0.12 | M10: 0.24 | N10: 0.41
A11: Benito Juarez | J11: C | K11: 140 | L11: 0.12 | M11: 0.24 | N11: 0.41
A12: Benito Juarez | B12: IN54BJUA02 | C12: Tres Arroyos 100 | D12: Argiudol tipico | E12: 10 | F12: 0.4 | G12: 81 | H12: 0.1 | I12: 0.5 | J12: AP | K12: 20 | L12: 0.15 | M12: 0.28 | N12: 0.5
A13: Benito Juarez | J13: B21T | K13: 40 | L13: 0.22 | M13: 0.34 | N13: 0.47
A14: Benito Juarez | J14: B21T | K14: 60 | L14: 0.22 | M14: 0.34 | N14: 0.43
A15: Benito Juarez | J15: B3 | K15: 90 | L15: 0.14 | M15: 0.27 | N15: 0.43
A16: Benito Juarez | J16: C | K16: 100 | L16: 0.12 | M16: 0.25 | N16: 0.41
A17: Coronel Suarez | B17: IN54SUAR01 | C17: La Colina 100 | D17: Hapludol típico | E17: 10 | F17: 0.4 | G17: 78 | H17: 0.1 | I17: 0.5 | J17: A1 | K17: 20 | L17: 0.13 | M17: 0.28 | N17: 0.54
A18: Coronel Suarez | J18: B2 | K18: 40 | L18: 0.13 | M18: 0.26 | N18: 0.47
A19: Coronel Suarez | J19: B2 | K19: 60 | L19: 0.13 | M19: 0.26 | N19: 0.45
A20: Coronel Suarez | J20: C1 | K20: 90 | L20: 0.11 | M20: 0.24 | N20: 0.41
A21: Coronel Suarez | J21: C1 | K21: 100 | L21: 0.11 | M21: 0.24 | N21: 0.41
A22: Coronel Suarez | B22: IN54SUAR02 | C22: La Colina 140 | D22: Hapludol típico | E22: 10 | F22: 0.4 | G22: 77 | H22: 0.1 | I22: 0.5 | J22: A1 | K22: 20 | L22: 0.13 | M22: 0.28 | N22: 0.54
A23: Coronel Suarez | J23: B2 | K23: 40 | L23: 0.13 | M23: 0.26 | N23: 0.47
A24: Coronel Suarez | J24: B2 | K24: 60 | L24: 0.13 | M24: 0.26 | N24: 0.45
A25: Coronel Suarez | J25: C1 | K25: 90 | L25: 0.11 | M25: 0.24 | N25: 0.41
A26: Coronel Suarez | J26: C1 | K26: 120 | L26: 0.11 | M26: 0.24 | N26: 0.41
A27: Coronel Suarez | J27: C2CA | K27: 140 | L27: 0.08 | M27: 0.2 | N27: 0.39
A28: Gualeguaychu | B28: IN65GUAL01 | C28: LA EMILIANA | D28: ARGIUDOL ACUICO | E28: 10 | F28: 0.4 | G28: 81 | H28: 0.08 | I28: 0.5 | J28: A1 | K28: 20 | L28: 0.16 | M28: 0.31 | N28: 0.52
A29: Gualeguaychu | J29: B2 | K29: 40 | L29: 0.26 | M29: 0.4 | N29: 0.47
A30: Gualeguaychu | J30: B2 | K30: 60 | L30: 0.26 | M30: 0.39 | N30: 0.47
A31: Gualeguaychu | J31: B2 | K31: 90 | L31: 0.27 | M31: 0.4 | N31: 0.45
A32: Gualeguaychu | J32: C | K32: 120 | L32: 0.24 | M32: 0.37 | N32: 0.43
A33: Gualeguaychu | J33: C | K33: 150 | L33: 0.24 | M33: 0.37 | N33: 0.43
A34: Gualeguaychu | J34: C | K34: 180 | L34: 0.24 | M34: 0.37 | N34: 0.43
A35: Gualeguaychu | B35: IN65GUAL02 | C35: LA PAULINA | D35: PELLUDERT ARGIUDOLICO | E35: 11 | F35: 0.4 | G35: 86 | H35: 0.05 | I35: 0.7 | J35: AP | K35: 20 | L35: 0.18 | M35: 0.33 | N35: 0.52
A36: Gualeguaychu | J36: BT | K36: 40 | L36: 0.22 | M36: 0.36 | N36: 0.52
A37: Gualeguaychu | J37: BT | K37: 60 | L37: 0.22 | M37: 0.36 | N37: 0.5
A38: Gualeguaychu | J38: BT | K38: 90 | L38: 0.24 | M38: 0.38 | N38: 0.48
A39: Gualeguaychu | J39: C | K39: 120 | L39: 0.23 | M39: 0.37 | N39: 0.43
A40: Gualeguaychu | J40: C | K40: 150 | L40: 0.23 | M40: 0.37 | N40: 0.43
...

Sheet cultivo
A1: cultivo | B1: cultivar | C1: parametro | D1: valor | E1: unidad
A2: trigo | C2: Tb_a | D2: 0 | E2: °C | F2: temperatura base a (siembra-emergencia maíz y soja, emergencia-madurez fisiológica trigo)
A3: trigo | C3: UT_S-E | D3: 150 | E3: °C | F3: unidades térmicas entre siembra y emergencia
A4: trigo | C4: UT_E-fKcbIni | D4: 300 | E4: °C | F4: unidades térmicas entre emergencia y fin kcb inicial
A5: trigo | C5: UT_E-iKcbMax | D5: 1000 | E5: °C | F5: unidades térmicas entre emergencia e inicio kcb máximo
A6: trigo | C6: UT_E-ET | D6: 400 | E6: °C | F6: unidades térmicas entre emergencia y espiguilla terminal (trigo)
A7: trigo | B7: intermedio-corto | C7: RCF | D7: 0.7 | F7: respuesta del cultivar al fotoperíodo
A8: trigo | B8: intermedio-largo | C8: RCF | D8: 0.85 | F8: respuesta del cultivar al fotoperíodo
A9: trigo | C9: UT_ET-iPC | D9: 100 | E9: °C | F9: unidades térmicas entre espiguilla terminal e inicio período crítico (trigo)
A10: trigo | C10: UT_ET-Z71 | D10: 700 | E10: °C | F10: unidades térmicas entre espiguilla terminal y Z71 (trigo)
A11: trigo | C11: UT_ET-fPC | D11: 800 | E11: °C | F11: unidades térmicas entre espiguilla terminal y fin período crítico (trigo)
A12: trigo | C12: UT_fPC-MF | D12: 400 | E12: °C | F12: unidades térmicas entre fin período crítico y madurez fisiológica (trigo)
A13: maiz | C13: Tb_a | D13: 10 | E13: °C | F13: temperatura base a (siembra-emergencia maíz y soja, ciclo completo trigo)
A14: maiz | C14: UT_S-E | D14: 80 | E14: °C | F14: unidades térmicas entre siembra y emergencia
A15: maiz | C15: Tb_b | D15: 8 | E15: °C | F15: temperatura base b (emergencia-madurez fisológica maíz y soja)
A16: maiz | C16: UT_E-fKcbIni | D16: 120 | E16: °C | F16: unidades térmicas entre emergencia y fin kcb inicial
A17: maiz | C17: UT_E-iKcbMax | D17: 560 | E17: °C | F17: unidades térmicas entre emergencia e inicio kcb máximo
A18: maiz | B18: templado-corto | C18: UT_E-R2 | D18: 950 | E18: °C | F18: unidades térmicas entre emergencia y R2 (maíz)
A19: maiz | B19: templado-intermedio | C19: UT_E-R2 | D19: 1050 | E19: °C | F19: unidades térmicas entre emergencia y R2 (maíz)
A20: maiz | B20: tropical-intermedio | C20: UT_E-R2 | D20: 1150 | E20: °C | F20: unidades térmicas entre emergencia y R2 (maíz)
A21: maiz | B21: templado-corto | C21: UT_E-iPC | D21: 500 | E21: °C | F21: unidades térmicas entre emergencia e inicio período crítico (maíz)
A22: maiz | B22: templado-intermedio | C22: UT_E-iPC | D22: 600 | E22: °C | F22: unidades térmicas entre emergencia e inicio período crítico (maíz)
A23: maiz | B23: tropical-intermedio | C23: UT_E-iPC | D23: 700 | E23: °C | F23: unidades térmicas entre emergencia e inicio período crítico (maíz)
A24: maiz | B24: templado-corto | C24: UT_E-fPC | D24: 1050 | E24: °C | F24: unidades térmicas entre emergencia y fin período crítico (maíz)
A25: maiz | B25: templado-intermedio | C25: UT_E-fPC | D25: 1150 | E25: °C | F25: unidades térmicas entre emergencia y fin período crítico (maíz)
A26: maiz | B26: tropical-intermedio | C26: UT_E-fPC | D26: 1250 | E26: °C | F26: unidades térmicas entre emergencia y fin período crítico (maíz)
A27: maiz | B27: templado-corto | C27: UT_R2-MF | D27: 550 | E27: °C | F27: unidades térmicas entre R2 y madurez fisiológica (maíz)
A28: maiz | B28: templado-intermedio | C28: UT_R2-MF | D28: 650 | E28: °C | F28: unidades térmicas entre R2 y madurez fisiológica (maíz)
A29: maiz | B29: tropical-intermedio | C29: UT_R2-MF | D29: 700 | E29: °C | F29: unidades térmicas entre R2 y madurez fisiológica (maíz)
A30: soja | C30: Tb_a | D30: 10 | E30: °C | F30: temperatura base a (siembra-emergencia maíz y soja, emergencia-madurez fisiológica trigo)
A31: soja | C31: To_a | D31: 27 | E31: °C | F31: temperatura óptima a (soja)
A32: soja | C32: UT_S-E | D32: 100 | E32: °C | F32: unidades térmicas entre siembra y emergencia
A33: soja | C33: Tb_b | D33: 7 | E33: °C | F33: temperatura base b (emergencia-madurez fisológica maíz y soja)
A34: soja | C34: UT_E-fKcbIni | D34: 180 | E34: °C | F34: unidades térmicas entre emergencia y fin kcb inicial
A35: soja | C35: UT_E-iKcbMax | D35: 840 | E35: °C | F35: unidades térmicas entre emergencia e inicio kcb máximo
A36: soja | B36: GM 3C | C36: FpU_E-R1 | D36: 13.5 | E36: h | F36: fotoperíodo umbral entre emergencia y R1 (soja)
A37: soja | B37: GM 4L | C37: FpU_E-R1 | D37: 13 | E37: h | F37: fotoperíodo umbral entre emergencia y R1 (soja)
A38: soja | B38: GM 6C | C38: FpU_E-R1 | D38: 12.5 | E38: h | F38: fotoperíodo umbral entre emergencia y R1 (soja)
A39: soja | C39: UT_E-R1 | D39: 400 | E39: °C | F39: unidades térmicas entre emergencia y R1 (soja)
A40: soja | B40: GM 3C | C40: FpU_R1-MF | D40: 13 | E40: h | F40: fotoperíodo umbral entre R1 y adurez fisiológica (soja)
...

Sheet condiciones iniciales
A1: variable | B1: dato | C1: descripción | F1: localidad | G1: omm_id | H1: suelo
A2: omm_id | B2: 87480 | F2: A | G2: A | H2: A
A3: suelo | F3: A | G3: A | H3: B
A4: cultivo | B4: trigo | F4: A | G4: A | H4: C
A5: cultivar | B5: intermedio-largo
A6: dda_S | B6: 150

Sheet fenologia
A1: variable | B1: dato | E1: Parámetro | F1: Valor | H1: n | I1: fila_clima | J1: día_año | K1: Tm | L1: Fp | M1: incr S→E | N1: acum S→E | O1: incr E→simple | P1: acum E→simple | Q1: incr E→hito1 | R1: acum E→hito1 | S1: incr hito1→hito2 | T1: acum hito1→hito2 | U1: incr raíz (Tbc) | V1: acum raíz (Tbc) | W1: n (días desde siembra) | X1: Profundidad radical (m) | Y1: Kcb
A2: cultivo | B2: ='condiciones iniciales'!B4 -> trigo | E2: Tb_a | F2: =SUMIFS(cultivo!$D:$D,cultivo!$A:$A,$B$2,cultivo!$C:$C,"Tb_a") -> 0 | H2: 0 | I2: =$F$26+H2 -> 151 | J2: =IFERROR(INDEX(clima!$C:$C,$I2),"") -> 150 | K2: =IFERROR(INDEX(clima!$F:$F,$I2),"") -> 6.9 | L2: =IFERROR(INDEX(clima!$J:$J,$I2),"") -> 10.005329 | M2: =IF($K2="","",MAX(0,(IF($B$2="soja",MIN($K2,$F$4),$K2))-$F$2)) -> 6.9 | N2: =M2 -> 6.9 | O2: =IF($K2="","",IF($I2<$F$27,0,MAX(0,(IF($B$2="soja",MIN($K2,$F$4),$K2))-$F$3))) -> 0 | P2: =O2 -> 0 | Q2: =IF($K2="","",IF($I2<$F$27,0,IF($B$2="trigo",MAX(0,$K2-$F$2)*MAX(0,(1-(((20-MIN(20,$L2))^2)*(0.01*$F$8)))),IF($B$2="maiz",MAX(0,$K2-$F$3),IF($B$2="soja",MAX(0,MIN($K2,$F$4)-$F$3)*MIN(1,MAX(0,1-MAX(0,($L2-$F$17))*0.3)),0))))) -> 0 | R2: =Q2 -> 0 | S2: =IF($K2="","",IF($I2<$F$28,0,IF($B$2="trigo",MAX(0,$K2),IF($B$2="soja",MAX(0,MIN($K2,$F$4)-$F$3)*MIN(1,MAX(0,1-MAX(0,($L2-$F$19))*0.3)),0)))) -> 0 | T2: =S2 -> 0 | U2: =IF($K2="","",IF(OR($I2<$F$27,$I2>$F$42),0,MAX(0,$K2-$F$37))) -> 0 | V2: =U2 -> 0 | W2: =H2 -> 0 | X2: =IF($I2="","",IF($I2<$F$27,$F$38,IF($I2<=$F$42,$F$38+($F$39*$V2)/100,$F$38+($F$39*INDEX($V:$V,$F$42))/100))) -> 0.2 | Y2: =IF($I2="","",IF($I2<$F$27,0,IF($P2<=$F$6,$F$40,IF($P2>=$F$7,$F$41,$F$40+($F$41-$F$40)*($P2-$F$6)/($F$7-$F$6))))) -> 0
A3: cultivar | B3: ='condiciones iniciales'!B5 -> intermedio-largo | E3: Tb_b | F3: =IF($B$2="trigo",F2,SUMIFS(cultivo!$D:$D,cultivo!$A:$A,$B$2,cultivo!$C:$C,"Tb_b")) -> 0 | H3: =H2+1 -> 1 | I3: =$F$26+H3 -> 152 | J3: =IFERROR(INDEX(clima!$C:$C,$I3),"") -> 151 | K3: =IFERROR(INDEX(clima!$F:$F,$I3),"") -> 8.2 | L3: =IFERROR(INDEX(clima!$J:$J,$I3),"") -> 9.9900276 | M3: =IF($K3="","",MAX(0,(IF($B$2="soja",MIN($K3,$F$4),$K3))-$F$2)) -> 8.2 | N3: =IF(M3="",N2,N2+M3) -> 15.1 | O3: =IF($K3="","",IF($I3<$F$27,0,MAX(0,(IF($B$2="soja",MIN($K3,$F$4),$K3))-$F$3))) -> 0 | P3: =IF(O3="",P2,P2+O3) -> 0 | Q3: =IF($K3="","",IF($I3<$F$27,0,IF($B$2="trigo",MAX(0,$K3-$F$2)*MAX(0,(1-(((20-MIN(20,$L3))^2)*(0.01*$F$8)))),IF($B$2="maiz",MAX(0,$K3-$F$3),IF($B$2="soja",MAX(0,MIN($K3,$F$4)-$F$3)*MIN(1,MAX(0,1-MAX(0,($L3-$F$17))*0.3)),0))))) -> 0 | R3: =IF(Q3="",R2,R2+Q3) -> 0 | S3: =IF($K3="","",IF($I3<$F$28,0,IF($B$2="trigo",MAX(0,$K3),IF($B$2="soja",MAX(0,MIN($K3,$F$4)-$F$3)*MIN(1,MAX(0,1-MAX(0,($L3-$F$19))*0.3)),0)))) -> 0 | T3: =IF(S3="",T2,T2+S3) -> 0 | U3: =IF($K3="","",IF(OR($I3<$F$27,$I3>$F$42),0,MAX(0,$K3-$F$37))) -> 0 | V3: =IF(U3="",V2,V2+U3) -> 0 | W3: =H3 -> 1 | X3: =IF($I3="","",IF($I3<$F$27,$F$38,IF($I3<=$F$42,$F$38+($F$39*$V3)/100,$F$38+($F$39*INDEX($V:$V,$F$42))/100))) -> 0.2 | Y3: =IF($I3="","",IF($I3<$F$27,0,IF($P3<=$F$6,$F$40,IF($P3>=$F$7,$F$41,$F$40+($F$41-$F$40)*($P3-$F$6)/($F$7-$F$6))))) -> 0
A4: dda_S | B4: ='condiciones iniciales'!B6 -> 150 | E4: To_a | F4: =IF($B$2="soja",SUMIFS(cultivo!$D:$D,cultivo!$A:$A,$B$2,cultivo!$C:$C,"To_a"),"") | H4: =H3+1 -> 2 | I4: =$F$26+H4 -> 153 | J4: =IFERROR(INDEX(clima!$C:$C,$I4),"") -> 152 | K4: =IFERROR(INDEX(clima!$F:$F,$I4),"") -> 7.5 | L4: =IFERROR(INDEX(clima!$J:$J,$I4),"") -> 9.9753617 | M4: =IF($K4="","",MAX(0,(IF($B$2="soja",MIN($K4,$F$4),$K4))-$F$2)) -> 7.5 | N4: =IF(M4="",N3,N3+M4) -> 22.6 | O4: =IF($K4="","",IF($I4<$F$27,0,MAX(0,(IF($B$2="soja",MIN($K4,$F$4),$K4))-$F$3))) -> 0 | P4: =IF(O4="",P3,P3+O4) -> 0 | Q4: =IF($K4="","",IF($I4<$F$27,0,IF($B$2="trigo",MAX(0,$K4-$F$2)*MAX(0,(1-(((20-MIN(20,$L4))^2)*(0.01*$F$8)))),IF($B$2="maiz",MAX(0,$K4-$F$3),IF($B$2="soja",MAX(0,MIN($K4,$F$4)-$F$3)*MIN(1,MAX(0,1-MAX(0,($L4-$F$17))*0.3)),0))))) -> 0 | R4: =IF(Q4="",R3,R3+Q4) -> 0 | S4: =IF($K4="","",IF($I4<$F$28,0,IF($B$2="trigo",MAX(0,$K4),IF($B$2="soja",MAX(0,MIN($K4,$F$4)-$F$3)*MIN(1,MAX(0,1-MAX(0,($L4-$F$19))*0.3)),0)))) -> 0 | T4: =IF(S4="",T3,T3+S4) -> 0 | U4: =IF($K4="","",IF(OR($I4<$F$27,$I4>$F$42),0,MAX(0,$K4-$F$37))) -> 0 | V4: =IF(U4="",V3,V3+U4) -> 0 | W4: =H4 -> 2 | X4: =IF($I4="","",IF($I4<$F$27,$F$38,IF($I4<=$F$42,$F$38+($F$39*$V4)/100,$F$38+($F$39*INDEX($V:$V,$F$42))/100))) -> 0.2 | Y4: =IF($I4="","",IF($I4<$F$27,0,IF($P4<=$F$6,$F$40,IF($P4>=$F$7,$F$41,$F$40+($F$41-$F$40)*($P4-$F$6)/($F$7-$F$6))))) -> 0
A5: dda_E | B5: =IFERROR(IF(($F$26+COUNTIFS($I$2:$I$501,">="&$F$26,$N$2:$N$501,"<"&$F$5))>548,"Datos insuficientes",INDEX(clima!$C:$C,$F$26+COUNTIFS($I$2:$I$501,">="&$F$26,$N$2:$N$501,"<"&$F$5))),"Sin datos") -> 169 | C5: fecha emergencia | E5: UT_S-E | F5: =SUMIFS(cultivo!$D:$D,cultivo!$A:$A,$B$2,cultivo!$C:$C,"UT_S-E") -> 150 | H5: =H4+1 -> 3 | I5: =$F$26+H5 -> 154 | J5: =IFERROR(INDEX(clima!$C:$C,$I5),"") -> 153 | K5: =IFERROR(INDEX(clima!$F:$F,$I5),"") -> 7.6 | L5: =IFERROR(INDEX(clima!$J:$J,$I5),"") -> 9.9613399 | M5: =IF($K5="","",MAX(0,(IF($B$2="soja",MIN($K5,$F$4),$K5))-$F$2)) -> 7.6 | N5: =IF(M5="",N4,N4+M5) -> 30.2 | O5: =IF($K5="","",IF($I5<$F$27,0,MAX(0,(IF($B$2="soja",MIN($K5,$F$4),$K5))-$F$3))) -> 0 | P5: =IF(O5="",P4,P4+O5) -> 0 | Q5: =IF($K5="","",IF($I5<$F$27,0,IF($B$2="trigo",MAX(0,$K5-$F$2)*MAX(0,(1-(((20-MIN(20,$L5))^2)*(0.01*$F$8)))),IF($B$2="maiz",MAX(0,$K5-$F$3),IF($B$2="soja",MAX(0,MIN($K5,$F$4)-$F$3)*MIN(1,MAX(0,1-MAX(0,($L5-$F$17))*0.3)),0))))) -> 0 | R5: =IF(Q5="",R4,R4+Q5) -> 0 | S5: =IF($K5="","",IF($I5<$F$28,0,IF($B$2="trigo",MAX(0,$K5),IF($B$2="soja",MAX(0,MIN($K5,$F$4)-$F$3)*MIN(1,MAX(0,1-MAX(0,($L5-$F$19))*0.3)),0)))) -> 0 | T5: =IF(S5="",T4,T4+S5) -> 0 | U5: =IF($K5="","",IF(OR($I5<$F$27,$I5>$F$42),0,MAX(0,$K5-$F$37))) -> 0 | V5: =IF(U5="",V4,V4+U5) -> 0 | W5: =H5 -> 3 | X5: =IF($I5="","",IF($I5<$F$27,$F$38,IF($I5<=$F$42,$F$38+($F$39*$V5)/100,$F$38+($F$39*INDEX($V:$V,$F$42))/100))) -> 0.2 | Y5: =IF($I5="","",IF($I5<$F$27,0,IF($P5<=$F$6,$F$40,IF($P5>=$F$7,$F$41,$F$40+($F$41-$F$40)*($P5-$F$6)/($F$7-$F$6))))) -> 0
A6: dda_fKcbIni | B6: =IFERROR(IF(($F$27+COUNTIFS($I$2:$I$501,">="&$F$27,$P$2:$P$501,"<"&$F$6))>548,"Datos insuficientes",INDEX(clima!$C:$C,$F$27+COUNTIFS($I$2:$I$501,">="&$F$27,$P$2:$P$501,"<"&$F$6))),"Sin datos") -> 203 | C6: fecha fin kcb inicial | E6: UT_E-fKcbIni | F6: =SUMIFS(cultivo!$D:$D,cultivo!$A:$A,$B$2,cultivo!$C:$C,"UT_E-fKcbIni") -> 300 | H6: =H5+1 -> 4 | I6: =$F$26+H6 -> 155 | J6: =IFERROR(INDEX(clima!$C:$C,$I6),"") -> 154 | K6: =IFERROR(INDEX(clima!$F:$F,$I6),"") -> 6.2 | L6: =IFERROR(INDEX(clima!$J:$J,$I6),"") -> 9.9479711 | M6: =IF($K6="","",MAX(0,(IF($B$2="soja",MIN($K6,$F$4),$K6))-$F$2)) -> 6.2 | N6: =IF(M6="",N5,N5+M6) -> 36.4 | O6: =IF($K6="","",IF($I6<$F$27,0,MAX(0,(IF($B$2="soja",MIN($K6,$F$4),$K6))-$F$3))) -> 0 | P6: =IF(O6="",P5,P5+O6) -> 0 | Q6: =IF($K6="","",IF($I6<$F$27,0,IF($B$2="trigo",MAX(0,$K6-$F$2)*MAX(0,(1-(((20-MIN(20,$L6))^2)*(0.01*$F$8)))),IF($B$2="maiz",MAX(0,$K6-$F$3),IF($B$2="soja",MAX(0,MIN($K6,$F$4)-$F$3)*MIN(1,MAX(0,1-MAX(0,($L6-$F$17))*0.3)),0))))) -> 0 | R6: =IF(Q6="",R5,R5+Q6) -> 0 | S6: =IF($K6="","",IF($I6<$F$28,0,IF($B$2="trigo",MAX(0,$K6),IF($B$2="soja",MAX(0,MIN($K6,$F$4)-$F$3)*MIN(1,MAX(0,1-MAX(0,($L6-$F$19))*0.3)),0)))) -> 0 | T6: =IF(S6="",T5,T5+S6) -> 0 | U6: =IF($K6="","",IF(OR($I6<$F$27,$I6>$F$42),0,MAX(0,$K6-$F$37))) -> 0 | V6: =IF(U6="",V5,V5+U6) -> 0 | W6: =H6 -> 4 | X6: =IF($I6="","",IF($I6<$F$27,$F$38,IF($I6<=$F$42,$F$38+($F$39*$V6)/100,$F$38+($F$39*INDEX($V:$V,$F$42))/100))) -> 0.2 | Y6: =IF($I6="","",IF($I6<$F$27,0,IF($P6<=$F$6,$F$40,IF($P6>=$F$7,$F$41,$F$40+($F$41-$F$40)*($P6-$F$6)/($F$7-$F$6))))) -> 0
A7: dda_iKcbMax | B7: =IFERROR(IF(($F$27+COUNTIFS($I$2:$I$501,">="&$F$27,$P$2:$P$501,"<"&$F$7))>548,"Datos insuficientes",INDEX(clima!$C:$C,$F$27+COUNTIFS($I$2:$I$501,">="&$F$27,$P$2:$P$501,"<"&$F$7))),"Sin datos") -> 267 | C7: fecha inicio kcb máximo | E7: UT_E-iKcbMax | F7: =SUMIFS(cultivo!$D:$D,cultivo!$A:$A,$B$2,cultivo!$C:$C,"UT_E-iKcbMax") -> 1000 | H7: =H6+1 -> 5 | I7: =$F$26+H7 -> 156 | J7: =IFERROR(INDEX(clima!$C:$C,$I7),"") -> 155 | K7: =IFERROR(INDEX(clima!$F:$F,$I7),"") -> 4.3 | L7: =IFERROR(INDEX(clima!$J:$J,$I7),"") -> 9.9352637 | M7: =IF($K7="","",MAX(0,(IF($B$2="soja",MIN($K7,$F$4),$K7))-$F$2)) -> 4.3 | N7: =IF(M7="",N6,N6+M7) -> 40.7 | O7: =IF($K7="","",IF($I7<$F$27,0,MAX(0,(IF($B$2="soja",MIN($K7,$F$4),$K7))-$F$3))) -> 0 | P7: =IF(O7="",P6,P6+O7) -> 0 | Q7: =IF($K7="","",IF($I7<$F$27,0,IF($B$2="trigo",MAX(0,$K7-$F$2)*MAX(0,(1-(((20-MIN(20,$L7))^2)*(0.01*$F$8)))),IF($B$2="maiz",MAX(0,$K7-$F$3),IF($B$2="soja",MAX(0,MIN($K7,$F$4)-$F$3)*MIN(1,MAX(0,1-MAX(0,($L7-$F$17))*0.3)),0))))) -> 0 | R7: =IF(Q7="",R6,R6+Q7) -> 0 | S7: =IF($K7="","",IF($I7<$F$28,0,IF($B$2="trigo",MAX(0,$K7),IF($B$2="soja",MAX(0,MIN($K7,$F$4)-$F$3)*MIN(1,MAX(0,1-MAX(0,($L7-$F$19))*0.3)),0)))) -> 0 | T7: =IF(S7="",T6,T6+S7) -> 0 | U7: =IF($K7="","",IF(OR($I7<$F$27,$I7>$F$42),0,MAX(0,$K7-$F$37))) -> 0 | V7: =IF(U7="",V6,V6+U7) -> 0 | W7: =H7 -> 5 | X7: =IF($I7="","",IF($I7<$F$27,$F$38,IF($I7<=$F$42,$F$38+($F$39*$V7)/100,$F$38+($F$39*INDEX($V:$V,$F$42))/100))) -> 0.2 | Y7: =IF($I7="","",IF($I7<$F$27,0,IF($P7<=$F$6,$F$40,IF($P7>=$F$7,$F$41,$F$40+($F$41-$F$40)*($P7-$F$6)/($F$7-$F$6))))) -> 0
A8: dda_ET | B8: =IF($B$2<>"trigo","",IFERROR(IF($F$28>548,"Datos insuficientes",INDEX(clima!$C:$C,$F$28)),"Sin datos")) -> 281 | C8: fecha espiguilla terminal (trigo) | E8: RCF (trigo) | F8: =IF($B$2="trigo",SUMIFS(cultivo!$D:$D,cultivo!$A:$A,"trigo",cultivo!$B:$B,$B$3,cultivo!$C:$C,"RCF"),"") -> 0.85 | H8: =H7+1 -> 6 | I8: =$F$26+H8 -> 157 | J8: =IFERROR(INDEX(clima!$C:$C,$I8),"") -> 156 | K8: =IFERROR(INDEX(clima!$F:$F,$I8),"") -> 4 | L8: =IFERROR(INDEX(clima!$J:$J,$I8),"") -> 9.9232257 | M8: =IF($K8="","",MAX(0,(IF($B$2="soja",MIN($K8,$F$4),$K8))-$F$2)) -> 4 | N8: =IF(M8="",N7,N7+M8) -> 44.7 | O8: =IF($K8="","",IF($I8<$F$27,0,MAX(0,(IF($B$2="soja",MIN($K8,$F$4),$K8))-$F$3))) -> 0 | P8: =IF(O8="",P7,P7+O8) -> 0 | Q8: =IF($K8="","",IF($I8<$F$27,0,IF($B$2="trigo",MAX(0,$K8-$F$2)*MAX(0,(1-(((20-MIN(20,$L8))^2)*(0.01*$F$8)))),IF($B$2="maiz",MAX(0,$K8-$F$3),IF($B$2="soja",MAX(0,MIN($K8,$F$4)-$F$3)*MIN(1,MAX(0,1-MAX(0,($L8-$F$17))*0.3)),0))))) -> 0 | R8: =IF(Q8="",R7,R7+Q8) -> 0 | S8: =IF($K8="","",IF($I8<$F$28,0,IF($B$2="trigo",MAX(0,$K8),IF($B$2="soja",MAX(0,MIN($K8,$F$4)-$F$3)*MIN(1,MAX(0,1-MAX(0,($L8-$F$19))*0.3)),0)))) -> 0 | T8: =IF(S8="",T7,T7+S8) -> 0 | U8: =IF($K8="","",IF(OR($I8<$F$27,$I8>$F$42),0,MAX(0,$K8-$F$37))) -> 0 | V8: =IF(U8="",V7,V7+U8) -> 0 | W8: =H8 -> 6 | X8: =IF($I8="","",IF($I8<$F$27,$F$38,IF($I8<=$F$42,$F$38+($F$39*$V8)/100,$F$38+($F$39*INDEX($V:$V,$F$42))/100))) -> 0.2 | Y8: =IF($I8="","",IF($I8<$F$27,0,IF($P8<=$F$6,$F$40,IF($P8>=$F$7,$F$41,$F$40+($F$41-$F$40)*($P8-$F$6)/($F$7-$F$6))))) -> 0
A9: dda_R1 | B9: =IF($B$2<>"soja","",IFERROR(IF($F$28>548,"Datos insuficientes",INDEX(clima!$C:$C,$F$28)),"Sin datos")) | C9: fecha R1 (soja) | E9: UT_E-ET (trigo) | F9: =IF($B$2="trigo",SUMIFS(cultivo!$D:$D,cultivo!$A:$A,"trigo",cultivo!$C:$C,"UT_E-ET"),"") -> 400 | H9: =H8+1 -> 7 | I9: =$F$26+H9 -> 158 | J9: =IFERROR(INDEX(clima!$C:$C,$I9),"") -> 157 | K9: =IFERROR(INDEX(clima!$F:$F,$I9),"") -> 7 | L9: =IFERROR(INDEX(clima!$J:$J,$I9),"") -> 9.911865 | M9: =IF($K9="","",MAX(0,(IF($B$2="soja",MIN($K9,$F$4),$K9))-$F$2)) -> 7 | N9: =IF(M9="",N8,N8+M9) -> 51.7 | O9: =IF($K9="","",IF($I9<$F$27,0,MAX(0,(IF($B$2="soja",MIN($K9,$F$4),$K9))-$F$3))) -> 0 | P9: =IF(O9="",P8,P8+O9) -> 0 | Q9: =IF($K9="","",IF($I9<$F$27,0,IF($B$2="trigo",MAX(0,$K9-$F$2)*MAX(0,(1-(((20-MIN(20,$L9))^2)*(0.01*$F$8)))),IF($B$2="maiz",MAX(0,$K9-$F$3),IF($B$2="soja",MAX(0,MIN($K9,$F$4)-$F$3)*MIN(1,MAX(0,1-MAX(0,($L9-$F$17))*0.3)),0))))) -> 0 | R9: =IF(Q9="",R8,R8+Q9) -> 0 | S9: =IF($K9="","",IF($I9<$F$28,0,IF($B$2="trigo",MAX(0,$K9),IF($B$2="soja",MAX(0,MIN($K9,$F$4)-$F$3)*MIN(1,MAX(0,1-MAX(0,($L9-$F$19))*0.3)),0)))) -> 0 | T9: =IF(S9="",T8,T8+S9) -> 0 | U9: =IF($K9="","",IF(OR($I9<$F$27,$I9>$F$42),0,MAX(0,$K9-$F$37))) -> 0 | V9: =IF(U9="",V8,V8+U9) -> 0 | W9: =H9 -> 7 | X9: =IF($I9="","",IF($I9<$F$27,$F$38,IF($I9<=$F$42,$F$38+($F$39*$V9)/100,$F$38+($F$39*INDEX($V:$V,$F$42))/100))) -> 0.2 | Y9: =IF($I9="","",IF($I9<$F$27,0,IF($P9<=$F$6,$F$40,IF($P9>=$F$7,$F$41,$F$40+($F$41-$F$40)*($P9-$F$6)/($F$7-$F$6))))) -> 0
A10: dda_R2 | B10: =IF($B$2<>"maiz","",IFERROR(IF($F$28>548,"Datos insuficientes",INDEX(clima!$C:$C,$F$28)),"Sin datos")) | C10: fecha R2 (maíz) | E10: UT_ET-iPC (trigo) | F10: =IF($B$2="trigo",SUMIFS(cultivo!$D:$D,cultivo!$A:$A,"trigo",cultivo!$C:$C,"UT_ET-iPC"),"") -> 100 | H10: =H9+1 -> 8 | I10: =$F$26+H10 -> 159 | J10: =IFERROR(INDEX(clima!$C:$C,$I10),"") -> 158 | K10: =IFERROR(INDEX(clima!$F:$F,$I10),"") -> 7.1 | L10: =IFERROR(INDEX(clima!$J:$J,$I10),"") -> 9.901189 | M10: =IF($K10="","",MAX(0,(IF($B$2="soja",MIN($K10,$F$4),$K10))-$F$2)) -> 7.1 | N10: =IF(M10="",N9,N9+M10) -> 58.8 | O10: =IF($K10="","",IF($I10<$F$27,0,MAX(0,(IF($B$2="soja",MIN($K10,$F$4),$K10))-$F$3))) -> 0 | P10: =IF(O10="",P9,P9+O10) -> 0 | Q10: =IF($K10="","",IF($I10<$F$27,0,IF($B$2="trigo",MAX(0,$K10-$F$2)*MAX(0,(1-(((20-MIN(20,$L10))^2)*(0.01*$F$8)))),IF($B$2="maiz",MAX(0,$K10-$F$3),IF($B$2="soja",MAX(0,MIN($K10,$F$4)-$F$3)*MIN(1,MAX(0,1-MAX(0,($L10-$F$17))*0.3)),0))))) -> 0 | R10: =IF(Q10="",R9,R9+Q10) -> 0 | S10: =IF($K10="","",IF($I10<$F$28,0,IF($B$2="trigo",MAX(0,$K10),IF($B$2="soja",MAX(0,MIN($K10,$F$4)-$F$3)*MIN(1,MAX(0,1-MAX(0,($L10-$F$19))*0.3)),0)))) -> 0 | T10: =IF(S10="",T9,T9+S10) -> 0 | U10: =IF($K10="","",IF(OR($I10<$F$27,$I10>$F$42),0,MAX(0,$K10-$F$37))) -> 0 | V10: =IF(U10="",V9,V9+U10) -> 0 | W10: =H10 -> 8 | X10: =IF($I10="","",IF($I10<$F$27,$F$38,IF($I10<=$F$42,$F$38+($F$39*$V10)/100,$F$38+($F$39*INDEX($V:$V,$F$42))/100))) -> 0.2 | Y10: =IF($I10="","",IF($I10<$F$27,0,IF($P10<=$F$6,$F$40,IF($P10>=$F$7,$F$41,$F$40+($F$41-$F$40)*($P10-$F$6)/($F$7-$F$6))))) -> 0
A11: dda_R5 | B11: =IF($B$2<>"soja","",IFERROR(IF(($F$28+COUNTIFS($I$2:$I$501,">="&$F$28,$T$2:$T$501,"<"&$F$20))>548,"Datos insuficientes",INDEX(clima!$C:$C,$F$28+COUNTIFS($I$2:$I$501,">="&$F$28,$T$2:$T$501,"<"&$F$20))),"Sin datos")) | C11: fecha R5 (soja) | E11: UT_ET-fPC (trigo) | F11: =IF($B$2="trigo",SUMIFS(cultivo!$D:$D,cultivo!$A:$A,"trigo",cultivo!$C:$C,"UT_ET-fPC"),"") -> 800 | H11: =H10+1 -> 9 | I11: =$F$26+H11 -> 160 | J11: =IFERROR(INDEX(clima!$C:$C,$I11),"") -> 159 | K11: =IFERROR(INDEX(clima!$F:$F,$I11),"") -> 7.1 | L11: =IFERROR(INDEX(clima!$J:$J,$I11),"") -> 9.8912045 | M11: =IF($K11="","",MAX(0,(IF($B$2="soja",MIN($K11,$F$4),$K11))-$F$2)) -> 7.1 | N11: =IF(M11="",N10,N10+M11) -> 65.9 | O11: =IF($K11="","",IF($I11<$F$27,0,MAX(0,(IF($B$2="soja",MIN($K11,$F$4),$K11))-$F$3))) -> 0 | P11: =IF(O11="",P10,P10+O11) -> 0 | Q11: =IF($K11="","",IF($I11<$F$27,0,IF($B$2="trigo",MAX(0,$K11-$F$2)*MAX(0,(1-(((20-MIN(20,$L11))^2)*(0.01*$F$8)))),IF($B$2="maiz",MAX(0,$K11-$F$3),IF($B$2="soja",MAX(0,MIN($K11,$F$4)-$F$3)*MIN(1,MAX(0,1-MAX(0,($L11-$F$17))*0.3)),0))))) -> 0 | R11: =IF(Q11="",R10,R10+Q11) -> 0 | S11: =IF($K11="","",IF($I11<$F$28,0,IF($B$2="trigo",MAX(0,$K11),IF($B$2="soja",MAX(0,MIN($K11,$F$4)-$F$3)*MIN(1,MAX(0,1-MAX(0,($L11-$F$19))*0.3)),0)))) -> 0 | T11: =IF(S11="",T10,T10+S11) -> 0 | U11: =IF($K11="","",IF(OR($I11<$F$27,$I11>$F$42),0,MAX(0,$K11-$F$37))) -> 0 | V11: =IF(U11="",V10,V10+U11) -> 0 | W11: =H11 -> 9 | X11: =IF($I11="","",IF($I11<$F$27,$F$38,IF($I11<=$F$42,$F$38+($F$39*$V11)/100,$F$38+($F$39*INDEX($V:$V,$F$42))/100))) -> 0.2 | Y11: =IF($I11="","",IF($I11<$F$27,0,IF($P11<=$F$6,$F$40,IF($P11>=$F$7,$F$41,$F$40+($F$41-$F$40)*($P11-$F$6)/($F$7-$F$6))))) -> 0
A12: dda_iPC | B12: =IFERROR(IF($B$2="trigo",IF(($F$28+COUNTIFS($I$2:$I$501,">="&$F$28,$T$2:$T$501,"<"&$F$10))>548,"Datos insuficientes",INDEX(clima!$C:$C,$F$28+COUNTIFS($I$2:$I$501,">="&$F$28,$T$2:$T$501,"<"&$F$10))),IF($B$2="maiz",IF(($F$27+COUNTIFS($I$2:$I$501,">="&$F$27,$P$2:$P$501,"<"&$F$14))>548,"Datos insuficientes",INDEX(clima!$C:$C,$F$27+COUNTIFS($I$2:$I$501,">="&$F$27,$P$2:$P$501,"<"&$F$14))),IF($B$2="soja",IF(($F$28+COUNTIFS($I$2:$I$501,">="&$F$28,$T$2:$T$501,"<"&$F$22))>548,"Datos insuficientes",INDEX(clima!$C:$C,$F$28+COUNTIFS($I$2:$I$501,">="&$F$28,$T$2:$T$501,"<"&$F$22))),""))),"Sin datos") -> 286 | C12: fecha inicio período crítico | E12: UT_fPC-MF (trigo) | F12: =IF($B$2="trigo",SUMIFS(cultivo!$D:$D,cultivo!$A:$A,"trigo",cultivo!$C:$C,"UT_fPC-MF"),"") -> 400 | H12: =H11+1 -> 10 | I12: =$F$26+H12 -> 161 | J12: =IFERROR(INDEX(clima!$C:$C,$I12),"") -> 160 | K12: =IFERROR(INDEX(clima!$F:$F,$I12),"") -> 7.6 | L12: =IFERROR(INDEX(clima!$J:$J,$I12),"") -> 9.8819182 | M12: =IF($K12="","",MAX(0,(IF($B$2="soja",MIN($K12,$F$4),$K12))-$F$2)) -> 7.6 | N12: =IF(M12="",N11,N11+M12) -> 73.5 | O12: =IF($K12="","",IF($I12<$F$27,0,MAX(0,(IF($B$2="soja",MIN($K12,$F$4),$K12))-$F$3))) -> 0 | P12: =IF(O12="",P11,P11+O12) -> 0 | Q12: =IF($K12="","",IF($I12<$F$27,0,IF($B$2="trigo",MAX(0,$K12-$F$2)*MAX(0,(1-(((20-MIN(20,$L12))^2)*(0.01*$F$8)))),IF($B$2="maiz",MAX(0,$K12-$F$3),IF($B$2="soja",MAX(0,MIN($K12,$F$4)-$F$3)*MIN(1,MAX(0,1-MAX(0,($L12-$F$17))*0.3)),0))))) -> 0 | R12: =IF(Q12="",R11,R11+Q12) -> 0 | S12: =IF($K12="","",IF($I12<$F$28,0,IF($B$2="trigo",MAX(0,$K12),IF($B$2="soja",MAX(0,MIN($K12,$F$4)-$F$3)*MIN(1,MAX(0,1-MAX(0,($L12-$F$19))*0.3)),0)))) -> 0 | T12: =IF(S12="",T11,T11+S12) -> 0 | U12: =IF($K12="","",IF(OR($I12<$F$27,$I12>$F$42),0,MAX(0,$K12-$F$37))) -> 0 | V12: =IF(U12="",V11,V11+U12) -> 0 | W12: =H12 -> 10 | X12: =IF($I12="","",IF($I12<$F$27,$F$38,IF($I12<=$F$42,$F$38+($F$39*$V12)/100,$F$38+($F$39*INDEX($V:$V,$F$42))/100))) -> 0.2 | Y12: =IF($I12="","",IF($I12<$F$27,0,IF($P12<=$F$6,$F$40,IF($P12>=$F$7,$F$41,$F$40+($F$41-$F$40)*($P12-$F$6)/($F$7-$F$6))))) -> 0
A13: dda_fPC | B13: =IFERROR(IF($B$2="trigo",IF(($F$28+COUNTIFS($I$2:$I$501,">="&$F$28,$T$2:$T$501,"<"&$F$11))>548,"Datos insuficientes",INDEX(clima!$C:$C,$F$28+COUNTIFS($I$2:$I$501,">="&$F$28,$T$2:$T$501,"<"&$F$11))),IF($B$2="maiz",IF(($F$27+COUNTIFS($I$2:$I$501,">="&$F$27,$P$2:$P$501,"<"&$F$15))>548,"Datos insuficientes",INDEX(clima!$C:$C,$F$27+COUNTIFS($I$2:$I$501,">="&$F$27,$P$2:$P$501,"<"&$F$15))),IF($B$2="soja",IF(($F$28+COUNTIFS($I$2:$I$501,">="&$F$28,$T$2:$T$501,"<"&($F$20+$F$23)))>548,"Datos insuficientes",INDEX(clima!$C:$C,$F$28+COUNTIFS($I$2:$I$501,">="&$F$28,$T$2:$T$501,"<"&($F$20+$F$23)))),""))),"Sin datos") -> 322 | C13: fecha fin período crítico | E13: UT_E-R2 (maiz) | F13: =IF($B$2="maiz",SUMIFS(cultivo!$D:$D,cultivo!$A:$A,"maiz",cultivo!$B:$B,$B$3,cultivo!$C:$C,"UT_E-R2"),"") | H13: =H12+1 -> 11 | I13: =$F$26+H13 -> 162 | J13: =IFERROR(INDEX(clima!$C:$C,$I13),"") -> 161 | K13: =IFERROR(INDEX(clima!$F:$F,$I13),"") -> 4.5 | L13: =IFERROR(INDEX(clima!$J:$J,$I13),"") -> 9.8733364 | M13: =IF($K13="","",MAX(0,(IF($B$2="soja",MIN($K13,$F$4),$K13))-$F$2)) -> 4.5 | N13: =IF(M13="",N12,N12+M13) -> 78 | O13: =IF($K13="","",IF($I13<$F$27,0,MAX(0,(IF($B$2="soja",MIN($K13,$F$4),$K13))-$F$3))) -> 0 | P13: =IF(O13="",P12,P12+O13) -> 0 | Q13: =IF($K13="","",IF($I13<$F$27,0,IF($B$2="trigo",MAX(0,$K13-$F$2)*MAX(0,(1-(((20-MIN(20,$L13))^2)*(0.01*$F$8)))),IF($B$2="maiz",MAX(0,$K13-$F$3),IF($B$2="soja",MAX(0,MIN($K13,$F$4)-$F$3)*MIN(1,MAX(0,1-MAX(0,($L13-$F$17))*0.3)),0))))) -> 0 | R13: =IF(Q13="",R12,R12+Q13) -> 0 | S13: =IF($K13="","",IF($I13<$F$28,0,IF($B$2="trigo",MAX(0,$K13),IF($B$2="soja",MAX(0,MIN($K13,$F$4)-$F$3)*MIN(1,MAX(0,1-MAX(0,($L13-$F$19))*0.3)),0)))) -> 0 | T13: =IF(S13="",T12,T12+S13) -> 0 | U13: =IF($K13="","",IF(OR($I13<$F$27,$I13>$F$42),0,MAX(0,$K13-$F$37))) -> 0 | V13: =IF(U13="",V12,V12+U13) -> 0 | W13: =H13 -> 11 | X13: =IF($I13="","",IF($I13<$F$27,$F$38,IF($I13<=$F$42,$F$38+($F$39*$V13)/100,$F$38+($F$39*INDEX($V:$V,$F$42))/100))) -> 0.2 | Y13: =IF($I13="","",IF($I13<$F$27,0,IF($P13<=$F$6,$F$40,IF($P13>=$F$7,$F$41,$F$40+($F$41-$F$40)*($P13-$F$6)/($F$7-$F$6))))) -> 0
A14: dda_MF | B14: =IFERROR(IF($B$2="trigo",IF(($F$28+COUNTIFS($I$2:$I$501,">="&$F$28,$T$2:$T$501,"<"&($F$11+$F$12)))>548,"Datos insuficientes",INDEX(clima!$C:$C,$F$28+COUNTIFS($I$2:$I$501,">="&$F$28,$T$2:$T$501,"<"&($F$11+$F$12)))),IF($B$2="maiz",IF(($F$27+COUNTIFS($I$2:$I$501,">="&$F$27,$P$2:$P$501,"<"&($F$13+$F$16)))>548,"Datos insuficientes",INDEX(clima!$C:$C,$F$27+COUNTIFS($I$2:$I$501,">="&$F$27,$P$2:$P$501,"<"&($F$13+$F$16)))),IF($B$2="soja",IF(($F$28+COUNTIFS($I$2:$I$501,">="&$F$28,$T$2:$T$501,"<"&($F$20+$F$21)))>548,"Datos insuficientes",INDEX(clima!$C:$C,$F$28+COUNTIFS($I$2:$I$501,">="&$F$28,$T$2:$T$501,"<"&($F$20+$F$21)))),""))),"Sin datos") -> 340 | C14: fecha madurez fisiológica | E14: UT_E-iPC (maiz) | F14: =IF($B$2="maiz",SUMIFS(cultivo!$D:$D,cultivo!$A:$A,"maiz",cultivo!$B:$B,$B$3,cultivo!$C:$C,"UT_E-iPC"),"") | H14: =H13+1 -> 12 | I14: =$F$26+H14 -> 163 | J14: =IFERROR(INDEX(clima!$C:$C,$I14),"") -> 162 | K14: =IFERROR(INDEX(clima!$F:$F,$I14),"") -> 6.7 | L14: =IFERROR(INDEX(clima!$J:$J,$I14),"") -> 9.8654647 | M14: =IF($K14="","",MAX(0,(IF($B$2="soja",MIN($K14,$F$4),$K14))-$F$2)) -> 6.7 | N14: =IF(M14="",N13,N13+M14) -> 84.7 | O14: =IF($K14="","",IF($I14<$F$27,0,MAX(0,(IF($B$2="soja",MIN($K14,$F$4),$K14))-$F$3))) -> 0 | P14: =IF(O14="",P13,P13+O14) -> 0 | Q14: =IF($K14="","",IF($I14<$F$27,0,IF($B$2="trigo",MAX(0,$K14-$F$2)*MAX(0,(1-(((20-MIN(20,$L14))^2)*(0.01*$F$8)))),IF($B$2="maiz",MAX(0,$K14-$F$3),IF($B$2="soja",MAX(0,MIN($K14,$F$4)-$F$3)*MIN(1,MAX(0,1-MAX(0,($L14-$F$17))*0.3)),0))))) -> 0 | R14: =IF(Q14="",R13,R13+Q14) -> 0 | S14: =IF($K14="","",IF($I14<$F$28,0,IF($B$2="trigo",MAX(0,$K14),IF($B$2="soja",MAX(0,MIN($K14,$F$4)-$F$3)*MIN(1,MAX(0,1-MAX(0,($L14-$F$19))*0.3)),0)))) -> 0 | T14: =IF(S14="",T13,T13+S14) -> 0 | U14: =IF($K14="","",IF(OR($I14<$F$27,$I14>$F$42),0,MAX(0,$K14-$F$37))) -> 0 | V14: =IF(U14="",V13,V13+U14) -> 0 | W14: =H14 -> 12 | X14: =IF($I14="","",IF($I14<$F$27,$F$38,IF($I14<=$F$42,$F$38+($F$39*$V14)/100,$F$38+($F$39*INDEX($V:$V,$F$42))/100))) -> 0.2 | Y14: =IF($I14="","",IF($I14<$F$27,0,IF($P14<=$F$6,$F$40,IF($P14>=$F$7,$F$41,$F$40+($F$41-$F$40)*($P14-$F$6)/($F$7-$F$6))))) -> 0
A15: dda_Z71 | B15: =IF($B$2<>"trigo","",IFERROR(IF(($F$28+COUNTIFS($I$2:$I$501,">="&$F$28,$T$2:$T$501,"<"&$F$43))>548,"Datos insuficientes",INDEX(clima!$C:$C,$F$28+COUNTIFS($I$2:$I$501,">="&$F$28,$T$2:$T$501,"<"&$F$43))),"Sin datos")) -> 317 | C15: fecha cuaje de granos Z71 (trigo) | E15: UT_E-fPC (maiz) | F15: =IF($B$2="maiz",SUMIFS(cultivo!$D:$D,cultivo!$A:$A,"maiz",cultivo!$B:$B,$B$3,cultivo!$C:$C,"UT_E-fPC"),"") | H15: =H14+1 -> 13 | I15: =$F$26+H15 -> 164 | J15: =IFERROR(INDEX(clima!$C:$C,$I15),"") -> 163 | K15: =IFERROR(INDEX(clima!$F:$F,$I15),"") -> 7.3 | L15: =IFERROR(INDEX(clima!$J:$J,$I15),"") -> 9.8583084 | M15: =IF($K15="","",MAX(0,(IF($B$2="soja",MIN($K15,$F$4),$K15))-$F$2)) -> 7.3 | N15: =IF(M15="",N14,N14+M15) -> 92 | O15: =IF($K15="","",IF($I15<$F$27,0,MAX(0,(IF($B$2="soja",MIN($K15,$F$4),$K15))-$F$3))) -> 0 | P15: =IF(O15="",P14,P14+O15) -> 0 | Q15: =IF($K15="","",IF($I15<$F$27,0,IF($B$2="trigo",MAX(0,$K15-$F$2)*MAX(0,(1-(((20-MIN(20,$L15))^2)*(0.01*$F$8)))),IF($B$2="maiz",MAX(0,$K15-$F$3),IF($B$2="soja",MAX(0,MIN($K15,$F$4)-$F$3)*MIN(1,MAX(0,1-MAX(0,($L15-$F$17))*0.3)),0))))) -> 0 | R15: =IF(Q15="",R14,R14+Q15) -> 0 | S15: =IF($K15="","",IF($I15<$F$28,0,IF($B$2="trigo",MAX(0,$K15),IF($B$2="soja",MAX(0,MIN($K15,$F$4)-$F$3)*MIN(1,MAX(0,1-MAX(0,($L15-$F$19))*0.3)),0)))) -> 0 | T15: =IF(S15="",T14,T14+S15) -> 0 | U15: =IF($K15="","",IF(OR($I15<$F$27,$I15>$F$42),0,MAX(0,$K15-$F$37))) -> 0 | V15: =IF(U15="",V14,V14+U15) -> 0 | W15: =H15 -> 13 | X15: =IF($I15="","",IF($I15<$F$27,$F$38,IF($I15<=$F$42,$F$38+($F$39*$V15)/100,$F$38+($F$39*INDEX($V:$V,$F$42))/100))) -> 0.2 | Y15: =IF($I15="","",IF($I15<$F$27,0,IF($P15<=$F$6,$F$40,IF($P15>=$F$7,$F$41,$F$40+($F$41-$F$40)*($P15-$F$6)/($F$7-$F$6))))) -> 0
E16: UT_R2-MF (maiz) | F16: =IF($B$2="maiz",SUMIFS(cultivo!$D:$D,cultivo!$A:$A,"maiz",cultivo!$B:$B,$B$3,cultivo!$C:$C,"UT_R2-MF"),"") | H16: =H15+1 -> 14 | I16: =$F$26+H16 -> 165 | J16: =IFERROR(INDEX(clima!$C:$C,$I16),"") -> 164 | K16: =IFERROR(INDEX(clima!$F:$F,$I16),"") -> 8.6 | L16: =IFERROR(INDEX(clima!$J:$J,$I16),"") -> 9.8518724 | M16: =IF($K16="","",MAX(0,(IF($B$2="soja",MIN($K16,$F$4),$K16))-$F$2)) -> 8.6 | N16: =IF(M16="",N15,N15+M16) -> 100.6 | O16: =IF($K16="","",IF($I16<$F$27,0,MAX(0,(IF($B$2="soja",MIN($K16,$F$4),$K16))-$F$3))) -> 0 | P16: =IF(O16="",P15,P15+O16) -> 0 | Q16: =IF($K16="","",IF($I16<$F$27,0,IF($B$2="trigo",MAX(0,$K16-$F$2)*MAX(0,(1-(((20-MIN(20,$L16))^2)*(0.01*$F$8)))),IF($B$2="maiz",MAX(0,$K16-$F$3),IF($B$2="soja",MAX(0,MIN($K16,$F$4)-$F$3)*MIN(1,MAX(0,1-MAX(0,($L16-$F$17))*0.3)),0))))) -> 0 | R16: =IF(Q16="",R15,R15+Q16) -> 0 | S16: =IF($K16="","",IF($I16<$F$28,0,IF($B$2="trigo",MAX(0,$K16),IF($B$2="soja",MAX(0,MIN($K16,$F$4)-$F$3)*MIN(1,MAX(0,1-MAX(0,($L16-$F$19))*0.3)),0)))) -> 0 | T16: =IF(S16="",T15,T15+S16) -> 0 | U16: =IF($K16="","",IF(OR($I16<$F$27,$I16>$F$42),0,MAX(0,$K16-$F$37))) -> 0 | V16: =IF(U16="",V15,V15+U16) -> 0 | W16: =H16 -> 14 | X16: =IF($I16="","",IF($I16<$F$27,$F$38,IF($I16<=$F$42,$F$38+($F$39*$V16)/100,$F$38+($F$39*INDEX($V:$V,$F$42))/100))) -> 0.2 | Y16: =IF($I16="","",IF($I16<$F$27,0,IF($P16<=$F$6,$F$40,IF($P16>=$F$7,$F$41,$F$40+($F$41-$F$40)*($P16-$F$6)/($F$7-$F$6))))) -> 0
E17: FpU_E-R1 (soja) | F17: =IF($B$2="soja",SUMIFS(cultivo!$D:$D,cultivo!$A:$A,"soja",cultivo!$B:$B,$B$3,cultivo!$C:$C,"FpU_E-R1"),"") | H17: =H16+1 -> 15 | I17: =$F$26+H17 -> 166 | J17: =IFERROR(INDEX(clima!$C:$C,$I17),"") -> 165 | K17: =IFERROR(INDEX(clima!$F:$F,$I17),"") -> 7.9 | L17: =IFERROR(INDEX(clima!$J:$J,$I17),"") -> 9.8461612 | M17: =IF($K17="","",MAX(0,(IF($B$2="soja",MIN($K17,$F$4),$K17))-$F$2)) -> 7.9 | N17: =IF(M17="",N16,N16+M17) -> 108.5 | O17: =IF($K17="","",IF($I17<$F$27,0,MAX(0,(IF($B$2="soja",MIN($K17,$F$4),$K17))-$F$3))) -> 0 | P17: =IF(O17="",P16,P16+O17) -> 0 | Q17: =IF($K17="","",IF($I17<$F$27,0,IF($B$2="trigo",MAX(0,$K17-$F$2)*MAX(0,(1-(((20-MIN(20,$L17))^2)*(0.01*$F$8)))),IF($B$2="maiz",MAX(0,$K17-$F$3),IF($B$2="soja",MAX(0,MIN($K17,$F$4)-$F$3)*MIN(1,MAX(0,1-MAX(0,($L17-$F$17))*0.3)),0))))) -> 0 | R17: =IF(Q17="",R16,R16+Q17) -> 0 | S17: =IF($K17="","",IF($I17<$F$28,0,IF($B$2="trigo",MAX(0,$K17),IF($B$2="soja",MAX(0,MIN($K17,$F$4)-$F$3)*MIN(1,MAX(0,1-MAX(0,($L17-$F$19))*0.3)),0)))) -> 0 | T17: =IF(S17="",T16,T16+S17) -> 0 | U17: =IF($K17="","",IF(OR($I17<$F$27,$I17>$F$42),0,MAX(0,$K17-$F$37))) -> 0 | V17: =IF(U17="",V16,V16+U17) -> 0 | W17: =H17 -> 15 | X17: =IF($I17="","",IF($I17<$F$27,$F$38,IF($I17<=$F$42,$F$38+($F$39*$V17)/100,$F$38+($F$39*INDEX($V:$V,$F$42))/100))) -> 0.2 | Y17: =IF($I17="","",IF($I17<$F$27,0,IF($P17<=$F$6,$F$40,IF($P17>=$F$7,$F$41,$F$40+($F$41-$F$40)*($P17-$F$6)/($F$7-$F$6))))) -> 0
E18: UT_E-R1 (soja) | F18: =IF($B$2="soja",SUMIFS(cultivo!$D:$D,cultivo!$A:$A,"soja",cultivo!$C:$C,"UT_E-R1"),"") | H18: =H17+1 -> 16 | I18: =$F$26+H18 -> 167 | J18: =IFERROR(INDEX(clima!$C:$C,$I18),"") -> 166 | K18: =IFERROR(INDEX(clima!$F:$F,$I18),"") -> 6.1 | L18: =IFERROR(INDEX(clima!$J:$J,$I18),"") -> 9.8411785 | M18: =IF($K18="","",MAX(0,(IF($B$2="soja",MIN($K18,$F$4),$K18))-$F$2)) -> 6.1 | N18: =IF(M18="",N17,N17+M18) -> 114.6 | O18: =IF($K18="","",IF($I18<$F$27,0,MAX(0,(IF($B$2="soja",MIN($K18,$F$4),$K18))-$F$3))) -> 0 | P18: =IF(O18="",P17,P17+O18) -> 0 | Q18: =IF($K18="","",IF($I18<$F$27,0,IF($B$2="trigo",MAX(0,$K18-$F$2)*MAX(0,(1-(((20-MIN(20,$L18))^2)*(0.01*$F$8)))),IF($B$2="maiz",MAX(0,$K18-$F$3),IF($B$2="soja",MAX(0,MIN($K18,$F$4)-$F$3)*MIN(1,MAX(0,1-MAX(0,($L18-$F$17))*0.3)),0))))) -> 0 | R18: =IF(Q18="",R17,R17+Q18) -> 0 | S18: =IF($K18="","",IF($I18<$F$28,0,IF($B$2="trigo",MAX(0,$K18),IF($B$2="soja",MAX(0,MIN($K18,$F$4)-$F$3)*MIN(1,MAX(0,1-MAX(0,($L18-$F$19))*0.3)),0)))) -> 0 | T18: =IF(S18="",T17,T17+S18) -> 0 | U18: =IF($K18="","",IF(OR($I18<$F$27,$I18>$F$42),0,MAX(0,$K18-$F$37))) -> 0 | V18: =IF(U18="",V17,V17+U18) -> 0 | W18: =H18 -> 16 | X18: =IF($I18="","",IF($I18<$F$27,$F$38,IF($I18<=$F$42,$F$38+($F$39*$V18)/100,$F$38+($F$39*INDEX($V:$V,$F$42))/100))) -> 0.2 | Y18: =IF($I18="","",IF($I18<$F$27,0,IF($P18<=$F$6,$F$40,IF($P18>=$F$7,$F$41,$F$40+($F$41-$F$40)*($P18-$F$6)/($F$7-$F$6))))) -> 0
E19: FpU_R1-MF (soja) | F19: =IF($B$2="soja",SUMIFS(cultivo!$D:$D,cultivo!$A:$A,"soja",cultivo!$B:$B,$B$3,cultivo!$C:$C,"FpU_R1-MF"),"") | H19: =H18+1 -> 17 | I19: =$F$26+H19 -> 168 | J19: =IFERROR(INDEX(clima!$C:$C,$I19),"") -> 167 | K19: =IFERROR(INDEX(clima!$F:$F,$I19),"") -> 10.5 | L19: =IFERROR(INDEX(clima!$J:$J,$I19),"") -> 9.8369279 | M19: =IF($K19="","",MAX(0,(IF($B$2="soja",MIN($K19,$F$4),$K19))-$F$2)) -> 10.5 | N19: =IF(M19="",N18,N18+M19) -> 125.1 | O19: =IF($K19="","",IF($I19<$F$27,0,MAX(0,(IF($B$2="soja",MIN($K19,$F$4),$K19))-$F$3))) -> 0 | P19: =IF(O19="",P18,P18+O19) -> 0 | Q19: =IF($K19="","",IF($I19<$F$27,0,IF($B$2="trigo",MAX(0,$K19-$F$2)*MAX(0,(1-(((20-MIN(20,$L19))^2)*(0.01*$F$8)))),IF($B$2="maiz",MAX(0,$K19-$F$3),IF($B$2="soja",MAX(0,MIN($K19,$F$4)-$F$3)*MIN(1,MAX(0,1-MAX(0,($L19-$F$17))*0.3)),0))))) -> 0 | R19: =IF(Q19="",R18,R18+Q19) -> 0 | S19: =IF($K19="","",IF($I19<$F$28,0,IF($B$2="trigo",MAX(0,$K19),IF($B$2="soja",MAX(0,MIN($K19,$F$4)-$F$3)*MIN(1,MAX(0,1-MAX(0,($L19-$F$19))*0.3)),0)))) -> 0 | T19: =IF(S19="",T18,T18+S19) -> 0 | U19: =IF($K19="","",IF(OR($I19<$F$27,$I19>$F$42),0,MAX(0,$K19-$F$37))) -> 0 | V19: =IF(U19="",V18,V18+U19) -> 0 | W19: =H19 -> 17 | X19: =IF($I19="","",IF($I19<$F$27,$F$38,IF($I19<=$F$42,$F$38+($F$39*$V19)/100,$F$38+($F$39*INDEX($V:$V,$F$42))/100))) -> 0.2 | Y19: =IF($I19="","",IF($I19<$F$27,0,IF($P19<=$F$6,$F$40,IF($P19>=$F$7,$F$41,$F$40+($F$41-$F$40)*($P19-$F$6)/($F$7-$F$6))))) -> 0
E20: UT-R1-R5 (soja) | F20: =IF($B$2="soja",SUMIFS(cultivo!$D:$D,cultivo!$A:$A,"soja",cultivo!$C:$C,"UT-R1-R5"),"") | H20: =H19+1 -> 18 | I20: =$F$26+H20 -> 169 | J20: =IFERROR(INDEX(clima!$C:$C,$I20),"") -> 168 | K20: =IFERROR(INDEX(clima!$F:$F,$I20),"") -> 14.1 | L20: =IFERROR(INDEX(clima!$J:$J,$I20),"") -> 9.8334122 | M20: =IF($K20="","",MAX(0,(IF($B$2="soja",MIN($K20,$F$4),$K20))-$F$2)) -> 14.1 | N20: =IF(M20="",N19,N19+M20) -> 139.2 | O20: =IF($K20="","",IF($I20<$F$27,0,MAX(0,(IF($B$2="soja",MIN($K20,$F$4),$K20))-$F$3))) -> 0 | P20: =IF(O20="",P19,P19+O20) -> 0 | Q20: =IF($K20="","",IF($I20<$F$27,0,IF($B$2="trigo",MAX(0,$K20-$F$2)*MAX(0,(1-(((20-MIN(20,$L20))^2)*(0.01*$F$8)))),IF($B$2="maiz",MAX(0,$K20-$F$3),IF($B$2="soja",MAX(0,MIN($K20,$F$4)-$F$3)*MIN(1,MAX(0,1-MAX(0,($L20-$F$17))*0.3)),0))))) -> 0 | R20: =IF(Q20="",R19,R19+Q20) -> 0 | S20: =IF($K20="","",IF($I20<$F$28,0,IF($B$2="trigo",MAX(0,$K20),IF($B$2="soja",MAX(0,MIN($K20,$F$4)-$F$3)*MIN(1,MAX(0,1-MAX(0,($L20-$F$19))*0.3)),0)))) -> 0 | T20: =IF(S20="",T19,T19+S20) -> 0 | U20: =IF($K20="","",IF(OR($I20<$F$27,$I20>$F$42),0,MAX(0,$K20-$F$37))) -> 0 | V20: =IF(U20="",V19,V19+U20) -> 0 | W20: =H20 -> 18 | X20: =IF($I20="","",IF($I20<$F$27,$F$38,IF($I20<=$F$42,$F$38+($F$39*$V20)/100,$F$38+($F$39*INDEX($V:$V,$F$42))/100))) -> 0.2 | Y20: =IF($I20="","",IF($I20<$F$27,0,IF($P20<=$F$6,$F$40,IF($P20>=$F$7,$F$41,$F$40+($F$41-$F$40)*($P20-$F$6)/($F$7-$F$6))))) -> 0
E21: UT-R5-MF (soja) | F21: =IF($B$2="soja",SUMIFS(cultivo!$D:$D,cultivo!$A:$A,"soja",cultivo!$C:$C,"UT-R5-MF"),"") | H21: =H20+1 -> 19 | I21: =$F$26+H21 -> 170 | J21: =IFERROR(INDEX(clima!$C:$C,$I21),"") -> 169 | K21: =IFERROR(INDEX(clima!$F:$F,$I21),"") -> 16.3 | L21: =IFERROR(INDEX(clima!$J:$J,$I21),"") -> 9.8306339 | M21: =IF($K21="","",MAX(0,(IF($B$2="soja",MIN($K21,$F$4),$K21))-$F$2)) -> 16.3 | N21: =IF(M21="",N20,N20+M21) -> 155.5 | O21: =IF($K21="","",IF($I21<$F$27,0,MAX(0,(IF($B$2="soja",MIN($K21,$F$4),$K21))-$F$3))) -> 16.3 | P21: =IF(O21="",P20,P20+O21) -> 16.3 | Q21: =IF($K21="","",IF($I21<$F$27,0,IF($B$2="trigo",MAX(0,$K21-$F$2)*MAX(0,(1-(((20-MIN(20,$L21))^2)*(0.01*$F$8)))),IF($B$2="maiz",MAX(0,$K21-$F$3),IF($B$2="soja",MAX(0,MIN($K21,$F$4)-$F$3)*MIN(1,MAX(0,1-MAX(0,($L21-$F$17))*0.3)),0))))) -> 1.9717123 | R21: =IF(Q21="",R20,R20+Q21) -> 1.9717123 | S21: =IF($K21="","",IF($I21<$F$28,0,IF($B$2="trigo",MAX(0,$K21),IF($B$2="soja",MAX(0,MIN($K21,$F$4)-$F$3)*MIN(1,MAX(0,1-MAX(0,($L21-$F$19))*0.3)),0)))) -> 0 | T21: =IF(S21="",T20,T20+S21) -> 0 | U21: =IF($K21="","",IF(OR($I21<$F$27,$I21>$F$42),0,MAX(0,$K21-$F$37))) -> 16.3 | V21: =IF(U21="",V20,V20+U21) -> 16.3 | W21: =H21 -> 19 | X21: =IF($I21="","",IF($I21<$F$27,$F$38,IF($I21<=$F$42,$F$38+($F$39*$V21)/100,$F$38+($F$39*INDEX($V:$V,$F$42))/100))) -> 0.22119 | Y21: =IF($I21="","",IF($I21<$F$27,0,IF($P21<=$F$6,$F$40,IF($P21>=$F$7,$F$41,$F$40+($F$41-$F$40)*($P21-$F$6)/($F$7-$F$6))))) -> 0.15
E22: UT_R1-iPC (soja) | F22: =IF($B$2="soja",SUMIFS(cultivo!$D:$D,cultivo!$A:$A,"soja",cultivo!$C:$C,"UT_R1-iPC"),"") | H22: =H21+1 -> 20 | I22: =$F$26+H22 -> 171 | J22: =IFERROR(INDEX(clima!$C:$C,$I22),"") -> 170 | K22: =IFERROR(INDEX(clima!$F:$F,$I22),"") -> 14.1 | L22: =IFERROR(INDEX(clima!$J:$J,$I22),"") -> 9.828595 | M22: =IF($K22="","",MAX(0,(IF($B$2="soja",MIN($K22,$F$4),$K22))-$F$2)) -> 14.1 | N22: =IF(M22="",N21,N21+M22) -> 169.6 | O22: =IF($K22="","",IF($I22<$F$27,0,MAX(0,(IF($B$2="soja",MIN($K22,$F$4),$K22))-$F$3))) -> 14.1 | P22: =IF(O22="",P21,P21+O22) -> 30.4 | Q22: =IF($K22="","",IF($I22<$F$27,0,IF($B$2="trigo",MAX(0,$K22-$F$2)*MAX(0,(1-(((20-MIN(20,$L22))^2)*(0.01*$F$8)))),IF($B$2="maiz",MAX(0,$K22-$F$3),IF($B$2="soja",MAX(0,MIN($K22,$F$4)-$F$3)*MIN(1,MAX(0,1-MAX(0,($L22-$F$17))*0.3)),0))))) -> 1.7006211 | R22: =IF(Q22="",R21,R21+Q22) -> 3.6723334 | S22: =IF($K22="","",IF($I22<$F$28,0,IF($B$2="trigo",MAX(0,$K22),IF($B$2="soja",MAX(0,MIN($K22,$F$4)-$F$3)*MIN(1,MAX(0,1-MAX(0,($L22-$F$19))*0.3)),0)))) -> 0 | T22: =IF(S22="",T21,T21+S22) -> 0 | U22: =IF($K22="","",IF(OR($I22<$F$27,$I22>$F$42),0,MAX(0,$K22-$F$37))) -> 14.1 | V22: =IF(U22="",V21,V21+U22) -> 30.4 | W22: =H22 -> 20 | X22: =IF($I22="","",IF($I22<$F$27,$F$38,IF($I22<=$F$42,$F$38+($F$39*$V22)/100,$F$38+($F$39*INDEX($V:$V,$F$42))/100))) -> 0.23952 | Y22: =IF($I22="","",IF($I22<$F$27,0,IF($P22<=$F$6,$F$40,IF($P22>=$F$7,$F$41,$F$40+($F$41-$F$40)*($P22-$F$6)/($F$7-$F$6))))) -> 0.15
E23: UT_R5-fPC (soja) | F23: =IF($B$2="soja",SUMIFS(cultivo!$D:$D,cultivo!$A:$A,"soja",cultivo!$C:$C,"UT_R5-fPC"),"") | H23: =H22+1 -> 21 | I23: =$F$26+H23 -> 172 | J23: =IFERROR(INDEX(clima!$C:$C,$I23),"") -> 171 | K23: =IFERROR(INDEX(clima!$F:$F,$I23),"") -> 13.8 | L23: =IFERROR(INDEX(clima!$J:$J,$I23),"") -> 9.8272968 | M23: =IF($K23="","",MAX(0,(IF($B$2="soja",MIN($K23,$F$4),$K23))-$F$2)) -> 13.8 | N23: =IF(M23="",N22,N22+M23) -> 183.4 | O23: =IF($K23="","",IF($I23<$F$27,0,MAX(0,(IF($B$2="soja",MIN($K23,$F$4),$K23))-$F$3))) -> 13.8 | P23: =IF(O23="",P22,P22+O23) -> 44.2 | Q23: =IF($K23="","",IF($I23<$F$27,0,IF($B$2="trigo",MAX(0,$K23-$F$2)*MAX(0,(1-(((20-MIN(20,$L23))^2)*(0.01*$F$8)))),IF($B$2="maiz",MAX(0,$K23-$F$3),IF($B$2="soja",MAX(0,MIN($K23,$F$4)-$F$3)*MIN(1,MAX(0,1-MAX(0,($L23-$F$17))*0.3)),0))))) -> 1.6613397 | R23: =IF(Q23="",R22,R22+Q23) -> 5.3336732 | S23: =IF($K23="","",IF($I23<$F$28,0,IF($B$2="trigo",MAX(0,$K23),IF($B$2="soja",MAX(0,MIN($K23,$F$4)-$F$3)*MIN(1,MAX(0,1-MAX(0,($L23-$F$19))*0.3)),0)))) -> 0 | T23: =IF(S23="",T22,T22+S23) -> 0 | U23: =IF($K23="","",IF(OR($I23<$F$27,$I23>$F$42),0,MAX(0,$K23-$F$37))) -> 13.8 | V23: =IF(U23="",V22,V22+U23) -> 44.2 | W23: =H23 -> 21 | X23: =IF($I23="","",IF($I23<$F$27,$F$38,IF($I23<=$F$42,$F$38+($F$39*$V23)/100,$F$38+($F$39*INDEX($V:$V,$F$42))/100))) -> 0.25746 | Y23: =IF($I23="","",IF($I23<$F$27,0,IF($P23<=$F$6,$F$40,IF($P23>=$F$7,$F$41,$F$40+($F$41-$F$40)*($P23-$F$6)/($F$7-$F$6))))) -> 0.15
H24: =H23+1 -> 22 | I24: =$F$26+H24 -> 173 | J24: =IFERROR(INDEX(clima!$C:$C,$I24),"") -> 172 | K24: =IFERROR(INDEX(clima!$F:$F,$I24),"") -> 13 | L24: =IFERROR(INDEX(clima!$J:$J,$I24),"") -> 9.8267403 | M24: =IF($K24="","",MAX(0,(IF($B$2="soja",MIN($K24,$F$4),$K24))-$F$2)) -> 13 | N24: =IF(M24="",N23,N23+M24) -> 196.4 | O24: =IF($K24="","",IF($I24<$F$27,0,MAX(0,(IF($B$2="soja",MIN($K24,$F$4),$K24))-$F$3))) -> 13 | P24: =IF(O24="",P23,P23+O24) -> 57.2 | Q24: =IF($K24="","",IF($I24<$F$27,0,IF($B$2="trigo",MAX(0,$K24-$F$2)*MAX(0,(1-(((20-MIN(20,$L24))^2)*(0.01*$F$8)))),IF($B$2="maiz",MAX(0,$K24-$F$3),IF($B$2="soja",MAX(0,MIN($K24,$F$4)-$F$3)*MIN(1,MAX(0,1-MAX(0,($L24-$F$17))*0.3)),0))))) -> 1.563779 | R24: =IF(Q24="",R23,R23+Q24) -> 6.8974521 | S24: =IF($K24="","",IF($I24<$F$28,0,IF($B$2="trigo",MAX(0,$K24),IF($B$2="soja",MAX(0,MIN($K24,$F$4)-$F$3)*MIN(1,MAX(0,1-MAX(0,($L24-$F$19))*0.3)),0)))) -> 0 | T24: =IF(S24="",T23,T23+S24) -> 0 | U24: =IF($K24="","",IF(OR($I24<$F$27,$I24>$F$42),0,MAX(0,$K24-$F$37))) -> 13 | V24: =IF(U24="",V23,V23+U24) -> 57.2 | W24: =H24 -> 22 | X24: =IF($I24="","",IF($I24<$F$27,$F$38,IF($I24<=$F$42,$F$38+($F$39*$V24)/100,$F$38+($F$39*INDEX($V:$V,$F$42))/100))) -> 0.27436 | Y24: =IF($I24="","",IF($I24<$F$27,0,IF($P24<=$F$6,$F$40,IF($P24>=$F$7,$F$41,$F$40+($F$41-$F$40)*($P24-$F$6)/($F$7-$F$6))))) -> 0.15
H25: =H24+1 -> 23 | I25: =$F$26+H25 -> 174 | J25: =IFERROR(INDEX(clima!$C:$C,$I25),"") -> 173 | K25: =IFERROR(INDEX(clima!$F:$F,$I25),"") -> 11.5 | L25: =IFERROR(INDEX(clima!$J:$J,$I25),"") -> 9.8269258 | M25: =IF($K25="","",MAX(0,(IF($B$2="soja",MIN($K25,$F$4),$K25))-$F$2)) -> 11.5 | N25: =IF(M25="",N24,N24+M25) -> 207.9 | O25: =IF($K25="","",IF($I25<$F$27,0,MAX(0,(IF($B$2="soja",MIN($K25,$F$4),$K25))-$F$3))) -> 11.5 | P25: =IF(O25="",P24,P24+O25) -> 68.7 | Q25: =IF($K25="","",IF($I25<$F$27,0,IF($B$2="trigo",MAX(0,$K25-$F$2)*MAX(0,(1-(((20-MIN(20,$L25))^2)*(0.01*$F$8)))),IF($B$2="maiz",MAX(0,$K25-$F$3),IF($B$2="soja",MAX(0,MIN($K25,$F$4)-$F$3)*MIN(1,MAX(0,1-MAX(0,($L25-$F$17))*0.3)),0))))) -> 1.3837119 | R25: =IF(Q25="",R24,R24+Q25) -> 8.2811641 | S25: =IF($K25="","",IF($I25<$F$28,0,IF($B$2="trigo",MAX(0,$K25),IF($B$2="soja",MAX(0,MIN($K25,$F$4)-$F$3)*MIN(1,MAX(0,1-MAX(0,($L25-$F$19))*0.3)),0)))) -> 0 | T25: =IF(S25="",T24,T24+S25) -> 0 | U25: =IF($K25="","",IF(OR($I25<$F$27,$I25>$F$42),0,MAX(0,$K25-$F$37))) -> 11.5 | V25: =IF(U25="",V24,V24+U25) -> 68.7 | W25: =H25 -> 23 | X25: =IF($I25="","",IF($I25<$F$27,$F$38,IF($I25<=$F$42,$F$38+($F$39*$V25)/100,$F$38+($F$39*INDEX($V:$V,$F$42))/100))) -> 0.28931 | Y25: =IF($I25="","",IF($I25<$F$27,0,IF($P25<=$F$6,$F$40,IF($P25>=$F$7,$F$41,$F$40+($F$41-$F$40)*($P25-$F$6)/($F$7-$F$6))))) -> 0.15
E26: fila_S (clima) | F26: =MATCH($B$4,clima!$C$2:$C$548,0)+1 -> 151 | H26: =H25+1 -> 24 | I26: =$F$26+H26 -> 175 | J26: =IFERROR(INDEX(clima!$C:$C,$I26),"") -> 174 | K26: =IFERROR(INDEX(clima!$F:$F,$I26),"") -> 6.9 | L26: =IFERROR(INDEX(clima!$J:$J,$I26),"") -> 9.8278533 | M26: =IF($K26="","",MAX(0,(IF($B$2="soja",MIN($K26,$F$4),$K26))-$F$2)) -> 6.9 | N26: =IF(M26="",N25,N25+M26) -> 214.8 | O26: =IF($K26="","",IF($I26<$F$27,0,MAX(0,(IF($B$2="soja",MIN($K26,$F$4),$K26))-$F$3))) -> 6.9 | P26: =IF(O26="",P25,P25+O26) -> 75.6 | Q26: =IF($K26="","",IF($I26<$F$27,0,IF($B$2="trigo",MAX(0,$K26-$F$2)*MAX(0,(1-(((20-MIN(20,$L26))^2)*(0.01*$F$8)))),IF($B$2="maiz",MAX(0,$K26-$F$3),IF($B$2="soja",MAX(0,MIN($K26,$F$4)-$F$3)*MIN(1,MAX(0,1-MAX(0,($L26-$F$17))*0.3)),0))))) -> 0.83133381 | R26: =IF(Q26="",R25,R25+Q26) -> 9.1124979 | S26: =IF($K26="","",IF($I26<$F$28,0,IF($B$2="trigo",MAX(0,$K26),IF($B$2="soja",MAX(0,MIN($K26,$F$4)-$F$3)*MIN(1,MAX(0,1-MAX(0,($L26-$F$19))*0.3)),0)))) -> 0 | T26: =IF(S26="",T25,T25+S26) -> 0 | U26: =IF($K26="","",IF(OR($I26<$F$27,$I26>$F$42),0,MAX(0,$K26-$F$37))) -> 6.9 | V26: =IF(U26="",V25,V25+U26) -> 75.6 | W26: =H26 -> 24 | X26: =IF($I26="","",IF($I26<$F$27,$F$38,IF($I26<=$F$42,$F$38+($F$39*$V26)/100,$F$38+($F$39*INDEX($V:$V,$F$42))/100))) -> 0.29828 | Y26: =IF($I26="","",IF($I26<$F$27,0,IF($P26<=$F$6,$F$40,IF($P26>=$F$7,$F$41,$F$40+($F$41-$F$40)*($P26-$F$6)/($F$7-$F$6))))) -> 0.15
E27: fila_E (clima) | F27: =$F$26+COUNTIFS($I$2:$I$501,">="&$F$26,$N$2:$N$501,"<"&$F$5) -> 170 | H27: =H26+1 -> 25 | I27: =$F$26+H27 -> 176 | J27: =IFERROR(INDEX(clima!$C:$C,$I27),"") -> 175 | K27: =IFERROR(INDEX(clima!$F:$F,$I27),"") -> 5.3 | L27: =IFERROR(INDEX(clima!$J:$J,$I27),"") -> 9.829522 | M27: =IF($K27="","",MAX(0,(IF($B$2="soja",MIN($K27,$F$4),$K27))-$F$2)) -> 5.3 | N27: =IF(M27="",N26,N26+M27) -> 220.1 | O27: =IF($K27="","",IF($I27<$F$27,0,MAX(0,(IF($B$2="soja",MIN($K27,$F$4),$K27))-$F$3))) -> 5.3 | P27: =IF(O27="",P26,P26+O27) -> 80.9 | Q27: =IF($K27="","",IF($I27<$F$27,0,IF($B$2="trigo",MAX(0,$K27-$F$2)*MAX(0,(1-(((20-MIN(20,$L27))^2)*(0.01*$F$8)))),IF($B$2="maiz",MAX(0,$K27-$F$3),IF($B$2="soja",MAX(0,MIN($K27,$F$4)-$F$3)*MIN(1,MAX(0,1-MAX(0,($L27-$F$17))*0.3)),0))))) -> 0.64009 | R27: =IF(Q27="",R26,R26+Q27) -> 9.7525879 | S27: =IF($K27="","",IF($I27<$F$28,0,IF($B$2="trigo",MAX(0,$K27),IF($B$2="soja",MAX(0,MIN($K27,$F$4)-$F$3)*MIN(1,MAX(0,1-MAX(0,($L27-$F$19))*0.3)),0)))) -> 0 | T27: =IF(S27="",T26,T26+S27) -> 0 | U27: =IF($K27="","",IF(OR($I27<$F$27,$I27>$F$42),0,MAX(0,$K27-$F$37))) -> 5.3 | V27: =IF(U27="",V26,V26+U27) -> 80.9 | W27: =H27 -> 25 | X27: =IF($I27="","",IF($I27<$F$27,$F$38,IF($I27<=$F$42,$F$38+($F$39*$V27)/100,$F$38+($F$39*INDEX($V:$V,$F$42))/100))) -> 0.30517 | Y27: =IF($I27="","",IF($I27<$F$27,0,IF($P27<=$F$6,$F$40,IF($P27>=$F$7,$F$41,$F$40+($F$41-$F$40)*($P27-$F$6)/($F$7-$F$6))))) -> 0.15
E28: fila_hito1 (ET trigo / R1 soja / R2 maiz) | F28: =$F$27+COUNTIFS($I$2:$I$501,">="&$F$27,$R$2:$R$501,"<"&IF($B$2="trigo",$F$9,IF($B$2="soja",$F$18,$F$13))) -> 282 | H28: =H27+1 -> 26 | I28: =$F$26+H28 -> 177 | J28: =IFERROR(INDEX(clima!$C:$C,$I28),"") -> 176 | K28: =IFERROR(INDEX(clima!$F:$F,$I28),"") -> 6.8 | L28: =IFERROR(INDEX(clima!$J:$J,$I28),"") -> 9.8319308 | M28: =IF($K28="","",MAX(0,(IF($B$2="soja",MIN($K28,$F$4),$K28))-$F$2)) -> 6.8 | N28: =IF(M28="",N27,N27+M28) -> 226.9 | O28: =IF($K28="","",IF($I28<$F$27,0,MAX(0,(IF($B$2="soja",MIN($K28,$F$4),$K28))-$F$3))) -> 6.8 | P28: =IF(O28="",P27,P27+O28) -> 87.7 | Q28: =IF($K28="","",IF($I28<$F$27,0,IF($B$2="trigo",MAX(0,$K28-$F$2)*MAX(0,(1-(((20-MIN(20,$L28))^2)*(0.01*$F$8)))),IF($B$2="maiz",MAX(0,$K28-$F$3),IF($B$2="soja",MAX(0,MIN($K28,$F$4)-$F$3)*MIN(1,MAX(0,1-MAX(0,($L28-$F$17))*0.3)),0))))) -> 0.82407926 | R28: =IF(Q28="",R27,R27+Q28) -> 10.576667 | S28: =IF($K28="","",IF($I28<$F$28,0,IF($B$2="trigo",MAX(0,$K28),IF($B$2="soja",MAX(0,MIN($K28,$F$4)-$F$3)*MIN(1,MAX(0,1-MAX(0,($L28-$F$19))*0.3)),0)))) -> 0 | T28: =IF(S28="",T27,T27+S28) -> 0 | U28: =IF($K28="","",IF(OR($I28<$F$27,$I28>$F$42),0,MAX(0,$K28-$F$37))) -> 6.8 | V28: =IF(U28="",V27,V27+U28) -> 87.7 | W28: =H28 -> 26 | X28: =IF($I28="","",IF($I28<$F$27,$F$38,IF($I28<=$F$42,$F$38+($F$39*$V28)/100,$F$38+($F$39*INDEX($V:$V,$F$42))/100))) -> 0.31401 | Y28: =IF($I28="","",IF($I28<$F$27,0,IF($P28<=$F$6,$F$40,IF($P28>=$F$7,$F$41,$F$40+($F$41-$F$40)*($P28-$F$6)/($F$7-$F$6))))) -> 0.15
H29: =H28+1 -> 27 | I29: =$F$26+H29 -> 178 | J29: =IFERROR(INDEX(clima!$C:$C,$I29),"") -> 177 | K29: =IFERROR(INDEX(clima!$F:$F,$I29),"") -> 6.5 | L29: =IFERROR(INDEX(clima!$J:$J,$I29),"") -> 9.835078 | M29: =IF($K29="","",MAX(0,(IF($B$2="soja",MIN($K29,$F$4),$K29))-$F$2)) -> 6.5 | N29: =IF(M29="",N28,N28+M29) -> 233.4 | O29: =IF($K29="","",IF($I29<$F$27,0,MAX(0,(IF($B$2="soja",MIN($K29,$F$4),$K29))-$F$3))) -> 6.5 | P29: =IF(O29="",P28,P28+O29) -> 94.2 | Q29: =IF($K29="","",IF($I29<$F$27,0,IF($B$2="trigo",MAX(0,$K29-$F$2)*MAX(0,(1-(((20-MIN(20,$L29))^2)*(0.01*$F$8)))),IF($B$2="maiz",MAX(0,$K29-$F$3),IF($B$2="soja",MAX(0,MIN($K29,$F$4)-$F$3)*MIN(1,MAX(0,1-MAX(0,($L29-$F$17))*0.3)),0))))) -> 0.79125842 | R29: =IF(Q29="",R28,R28+Q29) -> 11.367926 | S29: =IF($K29="","",IF($I29<$F$28,0,IF($B$2="trigo",MAX(0,$K29),IF($B$2="soja",MAX(0,MIN($K29,$F$4)-$F$3)*MIN(1,MAX(0,1-MAX(0,($L29-$F$19))*0.3)),0)))) -> 0 | T29: =IF(S29="",T28,T28+S29) -> 0 | U29: =IF($K29="","",IF(OR($I29<$F$27,$I29>$F$42),0,MAX(0,$K29-$F$37))) -> 6.5 | V29: =IF(U29="",V28,V28+U29) -> 94.2 | W29: =H29 -> 27 | X29: =IF($I29="","",IF($I29<$F$27,$F$38,IF($I29<=$F$42,$F$38+($F$39*$V29)/100,$F$38+($F$39*INDEX($V:$V,$F$42))/100))) -> 0.32246 | Y29: =IF($I29="","",IF($I29<$F$27,0,IF($P29<=$F$6,$F$40,IF($P29>=$F$7,$F$41,$F$40+($F$41-$F$40)*($P29-$F$6)/($F$7-$F$6))))) -> 0.15
E30: Notas del motor de cálculo (columnas E:T, auxiliares): | H30: =H29+1 -> 28 | I30: =$F$26+H30 -> 179 | J30: =IFERROR(INDEX(clima!$C:$C,$I30),"") -> 178 | K30: =IFERROR(INDEX(clima!$F:$F,$I30),"") -> 7 | L30: =IFERROR(INDEX(clima!$J:$J,$I30),"") -> 9.8389615 | M30: =IF($K30="","",MAX(0,(IF($B$2="soja",MIN($K30,$F$4),$K30))-$F$2)) -> 7 | N30: =IF(M30="",N29,N29+M30) -> 240.4 | O30: =IF($K30="","",IF($I30<$F$27,0,MAX(0,(IF($B$2="soja",MIN($K30,$F$4),$K30))-$F$3))) -> 7 | P30: =IF(O30="",P29,P29+O30) -> 101.2 | Q30: =IF($K30="","",IF($I30<$F$27,0,IF($B$2="trigo",MAX(0,$K30-$F$2)*MAX(0,(1-(((20-MIN(20,$L30))^2)*(0.01*$F$8)))),IF($B$2="maiz",MAX(0,$K30-$F$3),IF($B$2="soja",MAX(0,MIN($K30,$F$4)-$F$3)*MIN(1,MAX(0,1-MAX(0,($L30-$F$17))*0.3)),0))))) -> 0.85682112 | R30: =IF(Q30="",R29,R29+Q30) -> 12.224747 | S30: =IF($K30="","",IF($I30<$F$28,0,IF($B$2="trigo",MAX(0,$K30),IF($B$2="soja",MAX(0,MIN($K30,$F$4)-$F$3)*MIN(1,MAX(0,1-MAX(0,($L30-$F$19))*0.3)),0)))) -> 0 | T30: =IF(S30="",T29,T29+S30) -> 0 | U30: =IF($K30="","",IF(OR($I30<$F$27,$I30>$F$42),0,MAX(0,$K30-$F$37))) -> 7 | V30: =IF(U30="",V29,V29+U30) -> 101.2 | W30: =H30 -> 28 | X30: =IF($I30="","",IF($I30<$F$27,$F$38,IF($I30<=$F$42,$F$38+($F$39*$V30)/100,$F$38+($F$39*INDEX($V:$V,$F$42))/100))) -> 0.33156 | Y30: =IF($I30="","",IF($I30<$F$27,0,IF($P30<=$F$6,$F$40,IF($P30>=$F$7,$F$41,$F$40+($F$41-$F$40)*($P30-$F$6)/($F$7-$F$6))))) -> 0.15
